{
  "version": 8,
  "blockIdVersion": 11,
  "anchorX": 0,
  "anchorY": 0,
  "anchorZ": 0,
  "blocks": [
    {
      "x": -12,
      "y": 0,
      "z": -12,
      "name": "Rock_Shale_Cobble"
    },
    {
      "x": -12,
      "y": 1,
      "z": -12,
      "name": "Rock_Shale_Brick"
    },
    {
      "x": -12,
      "y": 2,
      "z": -12,
      "name": "Rock_Shale_Brick"
    },
    {
      "x": -12,
      "y": 3,
      "z": -12,
      "name": "Rock_Shale_Brick"
    },
    {
      "x": -12,
      "y": 4,
      "z": -12,
      "name": "Rock_Shale_Brick"
    },
    {
      "x": -12,
      "y": 5,
      "z": -12,
      "name": "Rock_Shale_Brick"
    },
    {
      "x": -12,
      "y": 6,
      "z": -12,
      "name": "Rock_Shale_Brick"
    },
    {
      "x": -12,
      "y": 7,
      "z": -12,
      "name": "Rock_Shale_Brick"
    },
    {
      "x": -12,
      "y": 8,
      "z": -12,
      "name": "Rock_Shale_Brick"
    },
    {
      "x": -12,
      "y": 9,
      "z": -12,
      "name": "Rock_Shale_Brick"
    },
    {
      "x": -12,
      "y": 0,
      "z": -11,
      "name": "Rock_Shale_Brick"
    },
    {
      "x": -12,
      "y": 1,
      "z": -11,
      "name": "Rock_Shale_Brick"
    },
    {
      "x": -12,
      "y": 2,
      "z": -11,
      "name": "Rock_Shale_Brick"
    },
    {
      "x": -12,
      "y": 3,
      "z": -11,
      "name": "Rock_Shale_Brick"
    },
    {
      "x": -12,
      "y": 4,
      "z": -11,
      "name": "Rock_Shale_Brick"
    },
    {
      "x": -12,
      "y": 5,
      "z": -11,
      "name": "Rock_Shale_Brick"
    },
    {
      "x": -12,
      "y": 6,
      "z": -11,
      "name": "Rock_Shale_Brick"
    },
    {
      "x": -12,
      "y": 7,
      "z": -11,
      "name": "Rock_Shale_Cobble"
    },
    {
      "x": -12,
      "y": 8,
      "z": -11,
      "name": "Rock_Shale_Brick"
    },
    {
      "x": -12,
      "y": 9,
      "z": -11,
      "name": "Rock_Shale_Brick"
    },
    {
      "x": -12,
      "y": 0,
      "z": -10,
      "name": "Rock_Shale_Brick"
    },
    {
      "x": -12,
      "y": 1,
      "z": -10,
      "name": "Rock_Shale_Brick"
    },
    {
      "x": -12,
      "y": 2,
      "z": -10,
      "name": "Rock_Shale_Brick"
    },
    {
      "x": -12,
      "y": 3,
      "z": -10,
      "name": "Rock_Shale_Brick"
    },
    {
      "x": -12,
      "y": 4,
      "z": -10,
      "name": "Rock_Shale_Brick"
    },
    {
      "x": -12,
      "y": 5,
      "z": -10,
      "name": "Rock_Shale_Brick"
    },
    {
      "x": -12,
      "y": 6,
      "z": -10,
      "name": "Rock_Shale_Brick"
    },
    {
      "x": -12,
      "y": 7,
      "z": -10,
      "name": "Rock_Shale_Brick"
    },
    {
      "x": -12,
      "y": 8,
      "z": -10,
      "name": "Rock_Shale_Cobble"
    },
    {
      "x": -12,
      "y": 9,
      "z": -10,
      "name": "Rock_Shale_Cobble"
    },
    {
      "x": -12,
      "y": 0,
      "z": -9,
      "name": "Rock_Shale_Cobble"
    },
    {
      "x": -12,
      "y": 1,
      "z": -9,
      "name": "Rock_Shale_Brick"
    },
    {
      "x": -12,
      "y": 2,
      "z": -9,
      "name": "Rock_Shale_Brick"
    },
    {
      "x": -12,
      "y": 3,
      "z": -9,
      "name": "Rock_Shale_Brick"
    },
    {
      "x": -12,
      "y": 4,
      "z": -9,
      "name": "Rock_Shale_Cobble"
    },
    {
      "x": -12,
      "y": 5,
      "z": -9,
      "name": "Rock_Shale_Brick"
    },
    {
      "x": -12,
      "y": 6,
      "z": -9,
      "name": "Rock_Shale_Brick"
    },
    {
      "x": -12,
      "y": 7,
      "z": -9,
      "name": "Rock_Shale_Brick"
    },
    {
      "x": -12,
      "y": 8,
      "z": -9,
      "name": "Rock_Shale_Cobble"
    },
    {
      "x": -12,
      "y": 9,
      "z": -9,
      "name": "Rock_Shale_Brick"
    },
    {
      "x": -12,
      "y": 0,
      "z": -8,
      "name": "Rock_Shale_Brick"
    },
    {
      "x": -12,
      "y": 1,
      "z": -8,
      "name": "Rock_Shale_Brick"
    },
    {
      "x": -12,
      "y": 2,
      "z": -8,
      "name": "Rock_Shale_Brick"
    },
    {
      "x": -12,
      "y": 3,
      "z": -8,
      "name": "Rock_Shale_Brick"
    },
    {
      "x": -12,
      "y": 4,
      "z": -8,
      "name": "Rock_Shale_Brick"
    },
    {
      "x": -12,
      "y": 5,
      "z": -8,
      "name": "Rock_Shale_Brick"
    },
    {
      "x": -12,
      "y": 6,
      "z": -8,
      "name": "Rock_Shale_Cobble"
    },
    {
      "x": -12,
      "y": 7,
      "z": -8,
      "name": "Rock_Shale_Brick"
    },
    {
      "x": -12,
      "y": 8,
      "z": -8,
      "name": "Rock_Shale_Brick"
    },
    {
      "x": -12,
      "y": 9,
      "z": -8,
      "name": "Rock_Shale_Brick"
    },
    {
      "x": -12,
      "y": 0,
      "z": -7,
      "name": "Rock_Shale_Brick"
    },
    {
      "x": -12,
      "y": 1,
      "z": -7,
      "name": "Rock_Shale_Brick"
    },
    {
      "x": -12,
      "y": 2,
      "z": -7,
      "name": "Rock_Shale_Brick"
    },
    {
      "x": -12,
      "y": 3,
      "z": -7,
      "name": "Rock_Shale_Cobble"
    },
    {
      "x": -12,
      "y": 4,
      "z": -7,
      "name": "Rock_Shale_Brick"
    },
    {
      "x": -12,
      "y": 5,
      "z": -7,
      "name": "Rock_Shale_Brick"
    },
    {
      "x": -12,
      "y": 6,
      "z": -7,
      "name": "Rock_Shale_Brick"
    },
    {
      "x": -12,
      "y": 7,
      "z": -7,
      "name": "Rock_Shale_Brick"
    },
    {
      "x": -12,
      "y": 8,
      "z": -7,
      "name": "Rock_Shale_Cobble"
    },
    {
      "x": -12,
      "y": 9,
      "z": -7,
      "name": "Rock_Shale_Brick"
    },
    {
      "x": -12,
      "y": 0,
      "z": -6,
      "name": "Rock_Shale_Brick"
    },
    {
      "x": -12,
      "y": 1,
      "z": -6,
      "name": "Rock_Shale_Brick"
    },
    {
      "x": -12,
      "y": 2,
      "z": -6,
      "name": "Rock_Shale_Cobble"
    },
    {
      "x": -12,
      "y": 3,
      "z": -6,
      "name": "Rock_Shale_Brick"
    },
    {
      "x": -12,
      "y": 4,
      "z": -6,
      "name": "Rock_Shale_Brick"
    },
    {
      "x": -12,
      "y": 5,
      "z": -6,
      "name": "Rock_Shale_Brick"
    },
    {
      "x": -12,
      "y": 6,
      "z": -6,
      "name": "Rock_Shale_Cobble"
    },
    {
      "x": -12,
      "y": 7,
      "z": -6,
      "name": "Rock_Shale_Brick"
    },
    {
      "x": -12,
      "y": 8,
      "z": -6,
      "name": "Rock_Shale_Brick"
    },
    {
      "x": -12,
      "y": 9,
      "z": -6,
      "name": "Rock_Shale_Brick"
    },
    {
      "x": -12,
      "y": 0,
      "z": -5,
      "name": "Rock_Shale_Brick"
    },
    {
      "x": -12,
      "y": 1,
      "z": -5,
      "name": "Rock_Shale_Brick"
    },
    {
      "x": -12,
      "y": 2,
      "z": -5,
      "name": "Rock_Shale_Cobble"
    },
    {
      "x": -12,
      "y": 3,
      "z": -5,
      "name": "Rock_Shale_Brick"
    },
    {
      "x": -12,
      "y": 4,
      "z": -5,
      "name": "Rock_Shale_Brick"
    },
    {
      "x": -12,
      "y": 5,
      "z": -5,
      "name": "Rock_Shale_Brick"
    },
    {
      "x": -12,
      "y": 6,
      "z": -5,
      "name": "Rock_Shale_Brick"
    },
    {
      "x": -12,
      "y": 7,
      "z": -5,
      "name": "Rock_Shale_Cobble"
    },
    {
      "x": -12,
      "y": 8,
      "z": -5,
      "name": "Rock_Shale_Brick"
    },
    {
      "x": -12,
      "y": 9,
      "z": -5,
      "name": "Rock_Shale_Brick"
    },
    {
      "x": -12,
      "y": 0,
      "z": -4,
      "name": "Rock_Shale_Brick"
    },
    {
      "x": -12,
      "y": 1,
      "z": -4,
      "name": "Rock_Shale_Cobble"
    },
    {
      "x": -12,
      "y": 2,
      "z": -4,
      "name": "Rock_Shale_Brick"
    },
    {
      "x": -12,
      "y": 3,
      "z": -4,
      "name": "Rock_Shale_Brick"
    },
    {
      "x": -12,
      "y": 4,
      "z": -4,
      "name": "Rock_Shale_Brick"
    },
    {
      "x": -12,
      "y": 5,
      "z": -4,
      "name": "Rock_Shale_Brick"
    },
    {
      "x": -12,
      "y": 6,
      "z": -4,
      "name": "Rock_Shale_Brick"
    },
    {
      "x": -12,
      "y": 7,
      "z": -4,
      "name": "Rock_Shale_Brick"
    },
    {
      "x": -12,
      "y": 8,
      "z": -4,
      "name": "Rock_Shale_Brick"
    },
    {
      "x": -12,
      "y": 9,
      "z": -4,
      "name": "Rock_Shale_Brick"
    },
    {
      "x": -12,
      "y": 0,
      "z": -3,
      "name": "Rock_Shale_Brick"
    },
    {
      "x": -12,
      "y": 1,
      "z": -3,
      "name": "Rock_Shale_Brick"
    },
    {
      "x": -12,
      "y": 2,
      "z": -3,
      "name": "Rock_Shale_Brick"
    },
    {
      "x": -12,
      "y": 3,
      "z": -3,
      "name": "Rock_Shale_Brick"
    },
    {
      "x": -12,
      "y": 4,
      "z": -3,
      "name": "Rock_Shale_Cobble"
    },
    {
      "x": -12,
      "y": 5,
      "z": -3,
      "name": "Rock_Shale_Brick"
    },
    {
      "x": -12,
      "y": 6,
      "z": -3,
      "name": "Rock_Shale_Cobble"
    },
    {
      "x": -12,
      "y": 7,
      "z": -3,
      "name": "Rock_Shale_Brick"
    },
    {
      "x": -12,
      "y": 8,
      "z": -3,
      "name": "Rock_Shale_Brick"
    },
    {
      "x": -12,
      "y": 9,
      "z": -3,
      "name": "Rock_Shale_Brick"
    },
    {
      "x": -12,
      "y": 0,
      "z": -2,
      "name": "Rock_Shale_Brick"
    },
    {
      "x": -12,
      "y": 1,
      "z": -2,
      "name": "Rock_Shale_Brick"
    },
    {
      "x": -12,
      "y": 2,
      "z": -2,
      "name": "Rock_Shale_Brick"
    },
    {
      "x": -12,
      "y": 3,
      "z": -2,
      "name": "Rock_Shale_Brick"
    },
    {
      "x": -12,
      "y": 4,
      "z": -2,
      "name": "Rock_Shale_Brick"
    },
    {
      "x": -12,
      "y": 5,
      "z": -2,
      "name": "Rock_Shale_Brick"
    },
    {
      "x": -12,
      "y": 6,
      "z": -2,
      "name": "Rock_Shale_Brick"
    },
    {
      "x": -12,
      "y": 7,
      "z": -2,
      "name": "Rock_Shale_Brick"
    },
    {
      "x": -12,
      "y": 8,
      "z": -2,
      "name": "Rock_Shale_Brick"
    },
    {
      "x": -12,
      "y": 9,
      "z": -2,
      "name": "Rock_Shale_Cobble"
    },
    {
      "x": -12,
      "y": 0,
      "z": -1,
      "name": "Rock_Shale_Brick"
    },
    {
      "x": -12,
      "y": 1,
      "z": -1,
      "name": "Rock_Shale_Brick"
    },
    {
      "x": -12,
      "y": 2,
      "z": -1,
      "name": "Rock_Shale_Cobble"
    },
    {
      "x": -12,
      "y": 3,
      "z": -1,
      "name": "Rock_Shale_Cobble"
    },
    {
      "x": -12,
      "y": 4,
      "z": -1,
      "name": "Rock_Shale_Brick"
    },
    {
      "x": -12,
      "y": 5,
      "z": -1,
      "name": "Rock_Shale_Brick"
    },
    {
      "x": -12,
      "y": 6,
      "z": -1,
      "name": "Rock_Shale_Cobble"
    },
    {
      "x": -12,
      "y": 7,
      "z": -1,
      "name": "Rock_Shale_Cobble"
    },
    {
      "x": -12,
      "y": 8,
      "z": -1,
      "name": "Rock_Shale_Brick"
    },
    {
      "x": -12,
      "y": 9,
      "z": -1,
      "name": "Rock_Shale_Cobble"
    },
    {
      "x": -12,
      "y": 0,
      "z": 0,
      "name": "Rock_Shale_Cobble"
    },
    {
      "x": -12,
      "y": 1,
      "z": 0,
      "name": "Rock_Shale_Brick"
    },
    {
      "x": -12,
      "y": 2,
      "z": 0,
      "name": "Rock_Shale_Brick"
    },
    {
      "x": -12,
      "y": 3,
      "z": 0,
      "name": "Rock_Shale_Brick"
    },
    {
      "x": -12,
      "y": 4,
      "z": 0,
      "name": "Rock_Shale_Brick"
    },
    {
      "x": -12,
      "y": 5,
      "z": 0,
      "name": "Rock_Shale_Brick"
    },
    {
      "x": -12,
      "y": 6,
      "z": 0,
      "name": "Rock_Shale_Brick"
    },
    {
      "x": -12,
      "y": 7,
      "z": 0,
      "name": "Rock_Shale_Brick"
    },
    {
      "x": -12,
      "y": 8,
      "z": 0,
      "name": "Rock_Shale_Brick"
    },
    {
      "x": -12,
      "y": 9,
      "z": 0,
      "name": "Rock_Shale_Brick"
    },
    {
      "x": -12,
      "y": 0,
      "z": 1,
      "name": "Rock_Shale_Brick"
    },
    {
      "x": -12,
      "y": 1,
      "z": 1,
      "name": "Rock_Shale_Brick"
    },
    {
      "x": -12,
      "y": 2,
      "z": 1,
      "name": "Rock_Shale_Brick"
    },
    {
      "x": -12,
      "y": 3,
      "z": 1,
      "name": "Rock_Shale_Brick"
    },
    {
      "x": -12,
      "y": 4,
      "z": 1,
      "name": "Rock_Shale_Brick"
    },
    {
      "x": -12,
      "y": 5,
      "z": 1,
      "name": "Rock_Shale_Brick"
    },
    {
      "x": -12,
      "y": 6,
      "z": 1,
      "name": "Rock_Shale_Brick"
    },
    {
      "x": -12,
      "y": 7,
      "z": 1,
      "name": "Rock_Shale_Brick"
    },
    {
      "x": -12,
      "y": 8,
      "z": 1,
      "name": "Rock_Shale_Cobble"
    },
    {
      "x": -12,
      "y": 9,
      "z": 1,
      "name": "Rock_Shale_Brick"
    },
    {
      "x": -12,
      "y": 0,
      "z": 2,
      "name": "Rock_Shale_Brick"
    },
    {
      "x": -12,
      "y": 1,
      "z": 2,
      "name": "Rock_Shale_Brick"
    },
    {
      "x": -12,
      "y": 2,
      "z": 2,
      "name": "Rock_Shale_Brick"
    },
    {
      "x": -12,
      "y": 3,
      "z": 2,
      "name": "Rock_Shale_Brick"
    },
    {
      "x": -12,
      "y": 4,
      "z": 2,
      "name": "Rock_Shale_Brick"
    },
    {
      "x": -12,
      "y": 5,
      "z": 2,
      "name": "Rock_Shale_Brick"
    },
    {
      "x": -12,
      "y": 6,
      "z": 2,
      "name": "Rock_Shale_Brick"
    },
    {
      "x": -12,
      "y": 7,
      "z": 2,
      "name": "Rock_Shale_Brick"
    },
    {
      "x": -12,
      "y": 8,
      "z": 2,
      "name": "Rock_Shale_Cobble"
    },
    {
      "x": -12,
      "y": 9,
      "z": 2,
      "name": "Rock_Shale_Brick"
    },
    {
      "x": -12,
      "y": 0,
      "z": 3,
      "name": "Rock_Shale_Brick"
    },
    {
      "x": -12,
      "y": 1,
      "z": 3,
      "name": "Rock_Shale_Brick"
    },
    {
      "x": -12,
      "y": 2,
      "z": 3,
      "name": "Rock_Shale_Cobble"
    },
    {
      "x": -12,
      "y": 3,
      "z": 3,
      "name": "Rock_Shale_Brick"
    },
    {
      "x": -12,
      "y": 4,
      "z": 3,
      "name": "Rock_Shale_Brick"
    },
    {
      "x": -12,
      "y": 5,
      "z": 3,
      "name": "Rock_Shale_Brick"
    },
    {
      "x": -12,
      "y": 6,
      "z": 3,
      "name": "Rock_Shale_Brick"
    },
    {
      "x": -12,
      "y": 7,
      "z": 3,
      "name": "Rock_Shale_Brick"
    },
    {
      "x": -12,
      "y": 8,
      "z": 3,
      "name": "Rock_Shale_Brick"
    },
    {
      "x": -12,
      "y": 9,
      "z": 3,
      "name": "Rock_Shale_Brick"
    },
    {
      "x": -12,
      "y": 0,
      "z": 4,
      "name": "Rock_Shale_Brick"
    },
    {
      "x": -12,
      "y": 1,
      "z": 4,
      "name": "Rock_Shale_Brick"
    },
    {
      "x": -12,
      "y": 2,
      "z": 4,
      "name": "Rock_Shale_Brick"
    },
    {
      "x": -12,
      "y": 3,
      "z": 4,
      "name": "Rock_Shale_Brick"
    },
    {
      "x": -12,
      "y": 4,
      "z": 4,
      "name": "Rock_Shale_Brick"
    },
    {
      "x": -12,
      "y": 5,
      "z": 4,
      "name": "Rock_Shale_Brick"
    },
    {
      "x": -12,
      "y": 6,
      "z": 4,
      "name": "Rock_Shale_Brick"
    },
    {
      "x": -12,
      "y": 7,
      "z": 4,
      "name": "Rock_Shale_Brick"
    },
    {
      "x": -12,
      "y": 8,
      "z": 4,
      "name": "Rock_Shale_Cobble"
    },
    {
      "x": -12,
      "y": 9,
      "z": 4,
      "name": "Rock_Shale_Brick"
    },
    {
      "x": -12,
      "y": 0,
      "z": 5,
      "name": "Rock_Shale_Brick"
    },
    {
      "x": -12,
      "y": 1,
      "z": 5,
      "name": "Rock_Shale_Cobble"
    },
    {
      "x": -12,
      "y": 2,
      "z": 5,
      "name": "Rock_Shale_Brick"
    },
    {
      "x": -12,
      "y": 3,
      "z": 5,
      "name": "Rock_Shale_Cobble"
    },
    {
      "x": -12,
      "y": 4,
      "z": 5,
      "name": "Rock_Shale_Cobble"
    },
    {
      "x": -12,
      "y": 5,
      "z": 5,
      "name": "Rock_Shale_Brick"
    },
    {
      "x": -12,
      "y": 6,
      "z": 5,
      "name": "Rock_Shale_Brick"
    },
    {
      "x": -12,
      "y": 7,
      "z": 5,
      "name": "Rock_Shale_Brick"
    },
    {
      "x": -12,
      "y": 8,
      "z": 5,
      "name": "Rock_Shale_Brick"
    },
    {
      "x": -12,
      "y": 9,
      "z": 5,
      "name": "Rock_Shale_Cobble"
    },
    {
      "x": -12,
      "y": 0,
      "z": 6,
      "name": "Rock_Shale_Cobble"
    },
    {
      "x": -12,
      "y": 1,
      "z": 6,
      "name": "Rock_Shale_Brick"
    },
    {
      "x": -12,
      "y": 2,
      "z": 6,
      "name": "Rock_Shale_Brick"
    },
    {
      "x": -12,
      "y": 3,
      "z": 6,
      "name": "Rock_Shale_Cobble"
    },
    {
      "x": -12,
      "y": 4,
      "z": 6,
      "name": "Rock_Shale_Brick"
    },
    {
      "x": -12,
      "y": 5,
      "z": 6,
      "name": "Rock_Shale_Brick"
    },
    {
      "x": -12,
      "y": 6,
      "z": 6,
      "name": "Rock_Shale_Brick"
    },
    {
      "x": -12,
      "y": 7,
      "z": 6,
      "name": "Rock_Shale_Brick"
    },
    {
      "x": -12,
      "y": 8,
      "z": 6,
      "name": "Rock_Shale_Brick"
    },
    {
      "x": -12,
      "y": 9,
      "z": 6,
      "name": "Rock_Shale_Brick"
    },
    {
      "x": -12,
      "y": 0,
      "z": 7,
      "name": "Rock_Shale_Brick"
    },
    {
      "x": -12,
      "y": 1,
      "z": 7,
      "name": "Rock_Shale_Cobble"
    },
    {
      "x": -12,
      "y": 2,
      "z": 7,
      "name": "Rock_Shale_Brick"
    },
    {
      "x": -12,
      "y": 3,
      "z": 7,
      "name": "Rock_Shale_Brick"
    },
    {
      "x": -12,
      "y": 4,
      "z": 7,
      "name": "Rock_Shale_Brick"
    },
    {
      "x": -12,
      "y": 5,
      "z": 7,
      "name": "Rock_Shale_Brick"
    },
    {
      "x": -12,
      "y": 6,
      "z": 7,
      "name": "Rock_Shale_Cobble"
    },
    {
      "x": -12,
      "y": 7,
      "z": 7,
      "name": "Rock_Shale_Brick"
    },
    {
      "x": -12,
      "y": 8,
      "z": 7,
      "name": "Rock_Shale_Brick"
    },
    {
      "x": -12,
      "y": 9,
      "z": 7,
      "name": "Rock_Shale_Brick"
    },
    {
      "x": -12,
      "y": 0,
      "z": 8,
      "name": "Rock_Shale_Brick"
    },
    {
      "x": -12,
      "y": 1,
      "z": 8,
      "name": "Rock_Shale_Cobble"
    },
    {
      "x": -12,
      "y": 2,
      "z": 8,
      "name": "Rock_Shale_Cobble"
    },
    {
      "x": -12,
      "y": 3,
      "z": 8,
      "name": "Rock_Shale_Brick"
    },
    {
      "x": -12,
      "y": 4,
      "z": 8,
      "name": "Rock_Shale_Brick"
    },
    {
      "x": -12,
      "y": 5,
      "z": 8,
      "name": "Rock_Shale_Brick"
    },
    {
      "x": -12,
      "y": 6,
      "z": 8,
      "name": "Rock_Shale_Brick"
    },
    {
      "x": -12,
      "y": 7,
      "z": 8,
      "name": "Rock_Shale_Brick"
    },
    {
      "x": -12,
      "y": 8,
      "z": 8,
      "name": "Rock_Shale_Brick"
    },
    {
      "x": -12,
      "y": 9,
      "z": 8,
      "name": "Rock_Shale_Brick"
    },
    {
      "x": -12,
      "y": 0,
      "z": 9,
      "name": "Rock_Shale_Cobble"
    },
    {
      "x": -12,
      "y": 1,
      "z": 9,
      "name": "Rock_Shale_Brick"
    },
    {
      "x": -12,
      "y": 2,
      "z": 9,
      "name": "Rock_Shale_Brick"
    },
    {
      "x": -12,
      "y": 3,
      "z": 9,
      "name": "Rock_Shale_Brick"
    },
    {
      "x": -12,
      "y": 4,
      "z": 9,
      "name": "Rock_Shale_Cobble"
    },
    {
      "x": -12,
      "y": 5,
      "z": 9,
      "name": "Rock_Shale_Brick"
    },
    {
      "x": -12,
      "y": 6,
      "z": 9,
      "name": "Rock_Shale_Brick"
    },
    {
      "x": -12,
      "y": 7,
      "z": 9,
      "name": "Rock_Shale_Brick"
    },
    {
      "x": -12,
      "y": 8,
      "z": 9,
      "name": "Rock_Shale_Cobble"
    },
    {
      "x": -12,
      "y": 9,
      "z": 9,
      "name": "Rock_Shale_Cobble"
    },
    {
      "x": -12,
      "y": 0,
      "z": 10,
      "name": "Rock_Shale_Cobble"
    },
    {
      "x": -12,
      "y": 1,
      "z": 10,
      "name": "Rock_Shale_Cobble"
    },
    {
      "x": -12,
      "y": 2,
      "z": 10,
      "name": "Rock_Shale_Brick"
    },
    {
      "x": -12,
      "y": 3,
      "z": 10,
      "name": "Rock_Shale_Brick"
    },
    {
      "x": -12,
      "y": 4,
      "z": 10,
      "name": "Rock_Shale_Brick"
    },
    {
      "x": -12,
      "y": 5,
      "z": 10,
      "name": "Rock_Shale_Brick"
    },
    {
      "x": -12,
      "y": 6,
      "z": 10,
      "name": "Rock_Shale_Brick"
    },
    {
      "x": -12,
      "y": 7,
      "z": 10,
      "name": "Rock_Shale_Cobble"
    },
    {
      "x": -12,
      "y": 8,
      "z": 10,
      "name": "Rock_Shale_Brick"
    },
    {
      "x": -12,
      "y": 9,
      "z": 10,
      "name": "Rock_Shale_Brick"
    },
    {
      "x": -12,
      "y": 0,
      "z": 11,
      "name": "Rock_Shale_Brick"
    },
    {
      "x": -12,
      "y": 1,
      "z": 11,
      "name": "Rock_Shale_Brick"
    },
    {
      "x": -12,
      "y": 2,
      "z": 11,
      "name": "Rock_Shale_Cobble"
    },
    {
      "x": -12,
      "y": 3,
      "z": 11,
      "name": "Rock_Shale_Cobble"
    },
    {
      "x": -12,
      "y": 4,
      "z": 11,
      "name": "Rock_Shale_Brick"
    },
    {
      "x": -12,
      "y": 5,
      "z": 11,
      "name": "Rock_Shale_Brick"
    },
    {
      "x": -12,
      "y": 6,
      "z": 11,
      "name": "Rock_Shale_Brick"
    },
    {
      "x": -12,
      "y": 7,
      "z": 11,
      "name": "Rock_Shale_Brick"
    },
    {
      "x": -12,
      "y": 8,
      "z": 11,
      "name": "Rock_Shale_Brick"
    },
    {
      "x": -12,
      "y": 9,
      "z": 11,
      "name": "Rock_Shale_Brick"
    },
    {
      "x": -12,
      "y": 0,
      "z": 12,
      "name": "Rock_Shale_Cobble"
    },
    {
      "x": -12,
      "y": 1,
      "z": 12,
      "name": "Rock_Shale_Brick"
    },
    {
      "x": -12,
      "y": 2,
      "z": 12,
      "name": "Rock_Shale_Brick"
    },
    {
      "x": -12,
      "y": 3,
      "z": 12,
      "name": "Rock_Shale_Brick"
    },
    {
      "x": -12,
      "y": 4,
      "z": 12,
      "name": "Rock_Shale_Brick"
    },
    {
      "x": -12,
      "y": 5,
      "z": 12,
      "name": "Rock_Shale_Cobble"
    },
    {
      "x": -12,
      "y": 6,
      "z": 12,
      "name": "Rock_Shale_Brick"
    },
    {
      "x": -12,
      "y": 7,
      "z": 12,
      "name": "Rock_Shale_Brick"
    },
    {
      "x": -12,
      "y": 8,
      "z": 12,
      "name": "Rock_Shale_Brick"
    },
    {
      "x": -12,
      "y": 9,
      "z": 12,
      "name": "Rock_Shale_Cobble"
    },
    {
      "x": -11,
      "y": 0,
      "z": -12,
      "name": "Rock_Shale_Cobble"
    },
    {
      "x": -11,
      "y": 1,
      "z": -12,
      "name": "Rock_Shale_Brick"
    },
    {
      "x": -11,
      "y": 2,
      "z": -12,
      "name": "Rock_Shale_Brick"
    },
    {
      "x": -11,
      "y": 3,
      "z": -12,
      "name": "Rock_Shale_Brick"
    },
    {
      "x": -11,
      "y": 4,
      "z": -12,
      "name": "Rock_Shale_Brick"
    },
    {
      "x": -11,
      "y": 5,
      "z": -12,
      "name": "Rock_Shale_Brick"
    },
    {
      "x": -11,
      "y": 6,
      "z": -12,
      "name": "Rock_Shale_Brick"
    },
    {
      "x": -11,
      "y": 7,
      "z": -12,
      "name": "Rock_Shale_Brick"
    },
    {
      "x": -11,
      "y": 8,
      "z": -12,
      "name": "Rock_Shale_Brick"
    },
    {
      "x": -11,
      "y": 9,
      "z": -12,
      "name": "Rock_Shale_Brick"
    },
    {
      "x": -11,
      "y": 0,
      "z": -11,
      "name": "Rock_Shale_Brick"
    },
    {
      "x": -11,
      "y": 1,
      "z": -11,
      "name": "Rock_Shale_Cobble"
    },
    {
      "x": -11,
      "y": 2,
      "z": -11,
      "name": "Rock_Shale_Brick"
    },
    {
      "x": -11,
      "y": 3,
      "z": -11,
      "name": "Rock_Shale_Brick"
    },
    {
      "x": -11,
      "y": 4,
      "z": -11,
      "name": "Rock_Shale_Brick"
    },
    {
      "x": -11,
      "y": 5,
      "z": -11,
      "name": "Rock_Shale_Brick"
    },
    {
      "x": -11,
      "y": 6,
      "z": -11,
      "name": "Rock_Shale_Brick"
    },
    {
      "x": -11,
      "y": 7,
      "z": -11,
      "name": "Rock_Shale_Brick"
    },
    {
      "x": -11,
      "y": 8,
      "z": -11,
      "name": "Rock_Shale_Cobble"
    },
    {
      "x": -11,
      "y": 9,
      "z": -11,
      "name": "Rock_Shale_Brick"
    },
    {
      "x": -11,
      "y": 0,
      "z": -10,
      "name": "Rock_Shale_Brick"
    },
    {
      "x": -11,
      "y": 1,
      "z": -10,
      "name": "Rock_Shale_Brick"
    },
    {
      "x": -11,
      "y": 2,
      "z": -10,
      "name": "Rock_Shale_Brick"
    },
    {
      "x": -11,
      "y": 3,
      "z": -10,
      "name": "Rock_Shale_Brick"
    },
    {
      "x": -11,
      "y": 4,
      "z": -10,
      "name": "Rock_Shale_Cobble"
    },
    {
      "x": -11,
      "y": 5,
      "z": -10,
      "name": "Rock_Shale_Brick"
    },
    {
      "x": -11,
      "y": 6,
      "z": -10,
      "name": "Rock_Shale_Cobble"
    },
    {
      "x": -11,
      "y": 7,
      "z": -10,
      "name": "Rock_Shale_Cobble"
    },
    {
      "x": -11,
      "y": 8,
      "z": -10,
      "name": "Rock_Shale_Brick"
    },
    {
      "x": -11,
      "y": 9,
      "z": -10,
      "name": "Rock_Shale_Cobble"
    },
    {
      "x": -11,
      "y": 0,
      "z": -9,
      "name": "Rock_Shale_Brick"
    },
    {
      "x": -11,
      "y": 1,
      "z": -9,
      "name": "Rock_Shale_Brick"
    },
    {
      "x": -11,
      "y": 2,
      "z": -9,
      "name": "Rock_Shale_Brick"
    },
    {
      "x": -11,
      "y": 3,
      "z": -9,
      "name": "Rock_Shale_Brick"
    },
    {
      "x": -11,
      "y": 4,
      "z": -9,
      "name": "Rock_Shale_Brick"
    },
    {
      "x": -11,
      "y": 5,
      "z": -9,
      "name": "Rock_Shale_Brick"
    },
    {
      "x": -11,
      "y": 6,
      "z": -9,
      "name": "Rock_Shale_Brick"
    },
    {
      "x": -11,
      "y": 7,
      "z": -9,
      "name": "Rock_Shale_Cobble"
    },
    {
      "x": -11,
      "y": 8,
      "z": -9,
      "name": "Rock_Shale_Cobble"
    },
    {
      "x": -11,
      "y": 9,
      "z": -9,
      "name": "Rock_Shale_Brick"
    },
    {
      "x": -11,
      "y": 0,
      "z": -8,
      "name": "Rock_Shale_Brick"
    },
    {
      "x": -11,
      "y": 1,
      "z": -8,
      "name": "Rock_Shale_Brick"
    },
    {
      "x": -11,
      "y": 2,
      "z": -8,
      "name": "Rock_Shale_Cobble"
    },
    {
      "x": -11,
      "y": 3,
      "z": -8,
      "name": "Rock_Shale_Brick"
    },
    {
      "x": -11,
      "y": 4,
      "z": -8,
      "name": "Rock_Shale_Brick"
    },
    {
      "x": -11,
      "y": 5,
      "z": -8,
      "name": "Rock_Shale_Cobble"
    },
    {
      "x": -11,
      "y": 6,
      "z": -8,
      "name": "Rock_Shale_Brick"
    },
    {
      "x": -11,
      "y": 7,
      "z": -8,
      "name": "Rock_Shale_Brick"
    },
    {
      "x": -11,
      "y": 8,
      "z": -8,
      "name": "Rock_Shale_Brick"
    },
    {
      "x": -11,
      "y": 9,
      "z": -8,
      "name": "Rock_Shale_Brick"
    },
    {
      "x": -11,
      "y": 0,
      "z": -7,
      "name": "Rock_Shale_Brick"
    },
    {
      "x": -11,
      "y": 1,
      "z": -7,
      "name": "Rock_Shale_Brick"
    },
    {
      "x": -11,
      "y": 2,
      "z": -7,
      "name": "Rock_Shale_Brick"
    },
    {
      "x": -11,
      "y": 3,
      "z": -7,
      "name": "Rock_Shale_Brick"
    },
    {
      "x": -11,
      "y": 4,
      "z": -7,
      "name": "Rock_Shale_Brick"
    },
    {
      "x": -11,
      "y": 5,
      "z": -7,
      "name": "Rock_Shale_Brick"
    },
    {
      "x": -11,
      "y": 6,
      "z": -7,
      "name": "Rock_Shale_Brick"
    },
    {
      "x": -11,
      "y": 7,
      "z": -7,
      "name": "Rock_Shale_Brick"
    },
    {
      "x": -11,
      "y": 8,
      "z": -7,
      "name": "Rock_Shale_Cobble"
    },
    {
      "x": -11,
      "y": 9,
      "z": -7,
      "name": "Rock_Shale_Brick"
    },
    {
      "x": -11,
      "y": 0,
      "z": -6,
      "name": "Rock_Shale_Brick"
    },
    {
      "x": -11,
      "y": 1,
      "z": -6,
      "name": "Rock_Shale_Brick"
    },
    {
      "x": -11,
      "y": 2,
      "z": -6,
      "name": "Rock_Shale_Brick"
    },
    {
      "x": -11,
      "y": 3,
      "z": -6,
      "name": "Rock_Shale_Brick"
    },
    {
      "x": -11,
      "y": 4,
      "z": -6,
      "name": "Rock_Shale_Brick"
    },
    {
      "x": -11,
      "y": 5,
      "z": -6,
      "name": "Rock_Shale_Brick"
    },
    {
      "x": -11,
      "y": 6,
      "z": -6,
      "name": "Rock_Shale_Cobble"
    },
    {
      "x": -11,
      "y": 7,
      "z": -6,
      "name": "Rock_Shale_Cobble"
    },
    {
      "x": -11,
      "y": 8,
      "z": -6,
      "name": "Rock_Shale_Brick"
    },
    {
      "x": -11,
      "y": 9,
      "z": -6,
      "name": "Rock_Shale_Brick"
    },
    {
      "x": -11,
      "y": 0,
      "z": -5,
      "name": "Rock_Shale_Cobble"
    },
    {
      "x": -11,
      "y": 1,
      "z": -5,
      "name": "Rock_Shale_Brick"
    },
    {
      "x": -11,
      "y": 2,
      "z": -5,
      "name": "Rock_Shale_Brick"
    },
    {
      "x": -11,
      "y": 3,
      "z": -5,
      "name": "Rock_Shale_Brick"
    },
    {
      "x": -11,
      "y": 4,
      "z": -5,
      "name": "Rock_Shale_Brick"
    },
    {
      "x": -11,
      "y": 5,
      "z": -5,
      "name": "Rock_Shale_Brick"
    },
    {
      "x": -11,
      "y": 6,
      "z": -5,
      "name": "Rock_Shale_Brick"
    },
    {
      "x": -11,
      "y": 7,
      "z": -5,
      "name": "Rock_Shale_Brick"
    },
    {
      "x": -11,
      "y": 8,
      "z": -5,
      "name": "Rock_Shale_Brick"
    },
    {
      "x": -11,
      "y": 9,
      "z": -5,
      "name": "Rock_Shale_Brick"
    },
    {
      "x": -11,
      "y": 0,
      "z": -4,
      "name": "Rock_Shale_Brick"
    },
    {
      "x": -11,
      "y": 1,
      "z": -4,
      "name": "Rock_Shale_Brick"
    },
    {
      "x": -11,
      "y": 2,
      "z": -4,
      "name": "Rock_Shale_Brick"
    },
    {
      "x": -11,
      "y": 3,
      "z": -4,
      "name": "Rock_Shale_Brick"
    },
    {
      "x": -11,
      "y": 4,
      "z": -4,
      "name": "Rock_Shale_Brick"
    },
    {
      "x": -11,
      "y": 5,
      "z": -4,
      "name": "Rock_Shale_Brick"
    },
    {
      "x": -11,
      "y": 6,
      "z": -4,
      "name": "Rock_Shale_Brick"
    },
    {
      "x": -11,
      "y": 7,
      "z": -4,
      "name": "Rock_Shale_Brick"
    },
    {
      "x": -11,
      "y": 8,
      "z": -4,
      "name": "Rock_Shale_Cobble"
    },
    {
      "x": -11,
      "y": 9,
      "z": -4,
      "name": "Rock_Shale_Brick"
    },
    {
      "x": -11,
      "y": 0,
      "z": -3,
      "name": "Rock_Shale_Brick"
    },
    {
      "x": -11,
      "y": 1,
      "z": -3,
      "name": "Rock_Shale_Brick"
    },
    {
      "x": -11,
      "y": 2,
      "z": -3,
      "name": "Rock_Shale_Brick"
    },
    {
      "x": -11,
      "y": 3,
      "z": -3,
      "name": "Rock_Shale_Brick"
    },
    {
      "x": -11,
      "y": 4,
      "z": -3,
      "name": "Rock_Shale_Brick"
    },
    {
      "x": -11,
      "y": 5,
      "z": -3,
      "name": "Rock_Shale_Brick"
    },
    {
      "x": -11,
      "y": 6,
      "z": -3,
      "name": "Rock_Shale_Brick"
    },
    {
      "x": -11,
      "y": 7,
      "z": -3,
      "name": "Rock_Shale_Brick"
    },
    {
      "x": -11,
      "y": 8,
      "z": -3,
      "name": "Rock_Shale_Brick"
    },
    {
      "x": -11,
      "y": 9,
      "z": -3,
      "name": "Rock_Shale_Cobble"
    },
    {
      "x": -11,
      "y": 0,
      "z": -2,
      "name": "Rock_Shale_Brick"
    },
    {
      "x": -11,
      "y": 1,
      "z": -2,
      "name": "Rock_Shale_Brick"
    },
    {
      "x": -11,
      "y": 2,
      "z": -2,
      "name": "Rock_Shale_Cobble"
    },
    {
      "x": -11,
      "y": 3,
      "z": -2,
      "name": "Rock_Shale_Brick"
    },
    {
      "x": -11,
      "y": 4,
      "z": -2,
      "name": "Rock_Shale_Brick"
    },
    {
      "x": -11,
      "y": 5,
      "z": -2,
      "name": "Rock_Shale_Cobble"
    },
    {
      "x": -11,
      "y": 6,
      "z": -2,
      "name": "Rock_Shale_Brick"
    },
    {
      "x": -11,
      "y": 7,
      "z": -2,
      "name": "Rock_Shale_Brick"
    },
    {
      "x": -11,
      "y": 8,
      "z": -2,
      "name": "Rock_Shale_Brick"
    },
    {
      "x": -11,
      "y": 9,
      "z": -2,
      "name": "Rock_Shale_Cobble"
    },
    {
      "x": -11,
      "y": 0,
      "z": -1,
      "name": "Rock_Shale_Brick"
    },
    {
      "x": -11,
      "y": 1,
      "z": -1,
      "name": "Rock_Shale_Brick"
    },
    {
      "x": -11,
      "y": 2,
      "z": -1,
      "name": "Rock_Shale_Brick"
    },
    {
      "x": -11,
      "y": 3,
      "z": -1,
      "name": "Rock_Shale_Cobble"
    },
    {
      "x": -11,
      "y": 4,
      "z": -1,
      "name": "Rock_Shale_Brick"
    },
    {
      "x": -11,
      "y": 5,
      "z": -1,
      "name": "Rock_Shale_Brick"
    },
    {
      "x": -11,
      "y": 6,
      "z": -1,
      "name": "Rock_Shale_Brick"
    },
    {
      "x": -11,
      "y": 7,
      "z": -1,
      "name": "Rock_Shale_Brick"
    },
    {
      "x": -11,
      "y": 8,
      "z": -1,
      "name": "Rock_Shale_Cobble"
    },
    {
      "x": -11,
      "y": 9,
      "z": -1,
      "name": "Rock_Shale_Cobble"
    },
    {
      "x": -11,
      "y": 0,
      "z": 0,
      "name": "Rock_Shale_Brick"
    },
    {
      "x": -11,
      "y": 1,
      "z": 0,
      "name": "Rock_Shale_Brick"
    },
    {
      "x": -11,
      "y": 2,
      "z": 0,
      "name": "Rock_Shale_Brick"
    },
    {
      "x": -11,
      "y": 3,
      "z": 0,
      "name": "Rock_Shale_Cobble"
    },
    {
      "x": -11,
      "y": 4,
      "z": 0,
      "name": "Rock_Shale_Brick"
    },
    {
      "x": -11,
      "y": 5,
      "z": 0,
      "name": "Rock_Shale_Brick"
    },
    {
      "x": -11,
      "y": 6,
      "z": 0,
      "name": "Rock_Shale_Brick"
    },
    {
      "x": -11,
      "y": 7,
      "z": 0,
      "name": "Rock_Shale_Cobble"
    },
    {
      "x": -11,
      "y": 8,
      "z": 0,
      "name": "Rock_Shale_Brick"
    },
    {
      "x": -11,
      "y": 9,
      "z": 0,
      "name": "Rock_Shale_Cobble"
    },
    {
      "x": -11,
      "y": 0,
      "z": 1,
      "name": "Rock_Shale_Brick"
    },
    {
      "x": -11,
      "y": 1,
      "z": 1,
      "name": "Rock_Shale_Brick"
    },
    {
      "x": -11,
      "y": 2,
      "z": 1,
      "name": "Rock_Shale_Brick"
    },
    {
      "x": -11,
      "y": 3,
      "z": 1,
      "name": "Rock_Shale_Cobble"
    },
    {
      "x": -11,
      "y": 4,
      "z": 1,
      "name": "Rock_Shale_Cobble"
    },
    {
      "x": -11,
      "y": 5,
      "z": 1,
      "name": "Rock_Shale_Cobble"
    },
    {
      "x": -11,
      "y": 6,
      "z": 1,
      "name": "Rock_Shale_Brick"
    },
    {
      "x": -11,
      "y": 7,
      "z": 1,
      "name": "Rock_Shale_Brick"
    },
    {
      "x": -11,
      "y": 8,
      "z": 1,
      "name": "Rock_Shale_Brick"
    },
    {
      "x": -11,
      "y": 9,
      "z": 1,
      "name": "Rock_Shale_Cobble"
    },
    {
      "x": -11,
      "y": 0,
      "z": 2,
      "name": "Rock_Shale_Brick"
    },
    {
      "x": -11,
      "y": 1,
      "z": 2,
      "name": "Rock_Shale_Brick"
    },
    {
      "x": -11,
      "y": 2,
      "z": 2,
      "name": "Rock_Shale_Brick"
    },
    {
      "x": -11,
      "y": 3,
      "z": 2,
      "name": "Rock_Shale_Cobble"
    },
    {
      "x": -11,
      "y": 4,
      "z": 2,
      "name": "Rock_Shale_Brick"
    },
    {
      "x": -11,
      "y": 5,
      "z": 2,
      "name": "Rock_Shale_Cobble"
    },
    {
      "x": -11,
      "y": 6,
      "z": 2,
      "name": "Rock_Shale_Brick"
    },
    {
      "x": -11,
      "y": 7,
      "z": 2,
      "name": "Rock_Shale_Brick"
    },
    {
      "x": -11,
      "y": 8,
      "z": 2,
      "name": "Rock_Shale_Cobble"
    },
    {
      "x": -11,
      "y": 9,
      "z": 2,
      "name": "Rock_Shale_Brick"
    },
    {
      "x": -11,
      "y": 0,
      "z": 3,
      "name": "Rock_Shale_Brick"
    },
    {
      "x": -11,
      "y": 1,
      "z": 3,
      "name": "Rock_Shale_Brick"
    },
    {
      "x": -11,
      "y": 2,
      "z": 3,
      "name": "Rock_Shale_Cobble"
    },
    {
      "x": -11,
      "y": 3,
      "z": 3,
      "name": "Rock_Shale_Brick"
    },
    {
      "x": -11,
      "y": 4,
      "z": 3,
      "name": "Rock_Shale_Brick"
    },
    {
      "x": -11,
      "y": 5,
      "z": 3,
      "name": "Rock_Shale_Cobble"
    },
    {
      "x": -11,
      "y": 6,
      "z": 3,
      "name": "Rock_Shale_Brick"
    },
    {
      "x": -11,
      "y": 7,
      "z": 3,
      "name": "Rock_Shale_Brick"
    },
    {
      "x": -11,
      "y": 8,
      "z": 3,
      "name": "Rock_Shale_Brick"
    },
    {
      "x": -11,
      "y": 9,
      "z": 3,
      "name": "Rock_Shale_Cobble"
    },
    {
      "x": -11,
      "y": 0,
      "z": 4,
      "name": "Rock_Shale_Brick"
    },
    {
      "x": -11,
      "y": 1,
      "z": 4,
      "name": "Rock_Shale_Brick"
    },
    {
      "x": -11,
      "y": 2,
      "z": 4,
      "name": "Rock_Shale_Brick"
    },
    {
      "x": -11,
      "y": 3,
      "z": 4,
      "name": "Rock_Shale_Brick"
    },
    {
      "x": -11,
      "y": 4,
      "z": 4,
      "name": "Rock_Shale_Brick"
    },
    {
      "x": -11,
      "y": 5,
      "z": 4,
      "name": "Rock_Shale_Brick"
    },
    {
      "x": -11,
      "y": 6,
      "z": 4,
      "name": "Rock_Shale_Cobble"
    },
    {
      "x": -11,
      "y": 7,
      "z": 4,
      "name": "Rock_Shale_Cobble"
    },
    {
      "x": -11,
      "y": 8,
      "z": 4,
      "name": "Rock_Shale_Brick"
    },
    {
      "x": -11,
      "y": 9,
      "z": 4,
      "name": "Rock_Shale_Brick"
    },
    {
      "x": -11,
      "y": 0,
      "z": 5,
      "name": "Rock_Shale_Brick"
    },
    {
      "x": -11,
      "y": 1,
      "z": 5,
      "name": "Rock_Shale_Brick"
    },
    {
      "x": -11,
      "y": 2,
      "z": 5,
      "name": "Rock_Shale_Brick"
    },
    {
      "x": -11,
      "y": 3,
      "z": 5,
      "name": "Rock_Shale_Cobble"
    },
    {
      "x": -11,
      "y": 4,
      "z": 5,
      "name": "Rock_Shale_Brick"
    },
    {
      "x": -11,
      "y": 5,
      "z": 5,
      "name": "Rock_Shale_Cobble"
    },
    {
      "x": -11,
      "y": 6,
      "z": 5,
      "name": "Rock_Shale_Brick"
    },
    {
      "x": -11,
      "y": 7,
      "z": 5,
      "name": "Rock_Shale_Brick"
    },
    {
      "x": -11,
      "y": 8,
      "z": 5,
      "name": "Rock_Shale_Cobble"
    },
    {
      "x": -11,
      "y": 9,
      "z": 5,
      "name": "Rock_Shale_Cobble"
    },
    {
      "x": -11,
      "y": 0,
      "z": 6,
      "name": "Rock_Shale_Brick"
    },
    {
      "x": -11,
      "y": 1,
      "z": 6,
      "name": "Rock_Shale_Brick"
    },
    {
      "x": -11,
      "y": 2,
      "z": 6,
      "name": "Rock_Shale_Brick"
    },
    {
      "x": -11,
      "y": 3,
      "z": 6,
      "name": "Rock_Shale_Brick"
    },
    {
      "x": -11,
      "y": 4,
      "z": 6,
      "name": "Rock_Shale_Brick"
    },
    {
      "x": -11,
      "y": 5,
      "z": 6,
      "name": "Rock_Shale_Brick"
    },
    {
      "x": -11,
      "y": 6,
      "z": 6,
      "name": "Rock_Shale_Brick"
    },
    {
      "x": -11,
      "y": 7,
      "z": 6,
      "name": "Rock_Shale_Brick"
    },
    {
      "x": -11,
      "y": 8,
      "z": 6,
      "name": "Rock_Shale_Brick"
    },
    {
      "x": -11,
      "y": 9,
      "z": 6,
      "name": "Rock_Shale_Brick"
    },
    {
      "x": -11,
      "y": 0,
      "z": 7,
      "name": "Rock_Shale_Brick"
    },
    {
      "x": -11,
      "y": 1,
      "z": 7,
      "name": "Rock_Shale_Cobble"
    },
    {
      "x": -11,
      "y": 2,
      "z": 7,
      "name": "Rock_Shale_Brick"
    },
    {
      "x": -11,
      "y": 3,
      "z": 7,
      "name": "Rock_Shale_Brick"
    },
    {
      "x": -11,
      "y": 4,
      "z": 7,
      "name": "Rock_Shale_Brick"
    },
    {
      "x": -11,
      "y": 5,
      "z": 7,
      "name": "Rock_Shale_Brick"
    },
    {
      "x": -11,
      "y": 6,
      "z": 7,
      "name": "Rock_Shale_Cobble"
    },
    {
      "x": -11,
      "y": 7,
      "z": 7,
      "name": "Rock_Shale_Brick"
    },
    {
      "x": -11,
      "y": 8,
      "z": 7,
      "name": "Rock_Shale_Brick"
    },
    {
      "x": -11,
      "y": 9,
      "z": 7,
      "name": "Rock_Shale_Brick"
    },
    {
      "x": -11,
      "y": 0,
      "z": 8,
      "name": "Rock_Shale_Brick"
    },
    {
      "x": -11,
      "y": 1,
      "z": 8,
      "name": "Rock_Shale_Brick"
    },
    {
      "x": -11,
      "y": 2,
      "z": 8,
      "name": "Rock_Shale_Brick"
    },
    {
      "x": -11,
      "y": 3,
      "z": 8,
      "name": "Rock_Shale_Brick"
    },
    {
      "x": -11,
      "y": 4,
      "z": 8,
      "name": "Rock_Shale_Brick"
    },
    {
      "x": -11,
      "y": 5,
      "z": 8,
      "name": "Rock_Shale_Brick"
    },
    {
      "x": -11,
      "y": 6,
      "z": 8,
      "name": "Rock_Shale_Brick"
    },
    {
      "x": -11,
      "y": 7,
      "z": 8,
      "name": "Rock_Shale_Brick"
    },
    {
      "x": -11,
      "y": 8,
      "z": 8,
      "name": "Rock_Shale_Cobble"
    },
    {
      "x": -11,
      "y": 9,
      "z": 8,
      "name": "Rock_Shale_Brick"
    },
    {
      "x": -11,
      "y": 0,
      "z": 9,
      "name": "Rock_Shale_Brick"
    },
    {
      "x": -11,
      "y": 1,
      "z": 9,
      "name": "Rock_Shale_Brick"
    },
    {
      "x": -11,
      "y": 2,
      "z": 9,
      "name": "Rock_Shale_Brick"
    },
    {
      "x": -11,
      "y": 3,
      "z": 9,
      "name": "Rock_Shale_Cobble"
    },
    {
      "x": -11,
      "y": 4,
      "z": 9,
      "name": "Rock_Shale_Brick"
    },
    {
      "x": -11,
      "y": 5,
      "z": 9,
      "name": "Rock_Shale_Brick"
    },
    {
      "x": -11,
      "y": 6,
      "z": 9,
      "name": "Rock_Shale_Cobble"
    },
    {
      "x": -11,
      "y": 7,
      "z": 9,
      "name": "Rock_Shale_Brick"
    },
    {
      "x": -11,
      "y": 8,
      "z": 9,
      "name": "Rock_Shale_Brick"
    },
    {
      "x": -11,
      "y": 9,
      "z": 9,
      "name": "Rock_Shale_Brick"
    },
    {
      "x": -11,
      "y": 0,
      "z": 10,
      "name": "Rock_Shale_Brick"
    },
    {
      "x": -11,
      "y": 1,
      "z": 10,
      "name": "Rock_Shale_Brick"
    },
    {
      "x": -11,
      "y": 2,
      "z": 10,
      "name": "Rock_Shale_Brick"
    },
    {
      "x": -11,
      "y": 3,
      "z": 10,
      "name": "Rock_Shale_Cobble"
    },
    {
      "x": -11,
      "y": 4,
      "z": 10,
      "name": "Rock_Shale_Brick"
    },
    {
      "x": -11,
      "y": 5,
      "z": 10,
      "name": "Rock_Shale_Brick"
    },
    {
      "x": -11,
      "y": 6,
      "z": 10,
      "name": "Rock_Shale_Brick"
    },
    {
      "x": -11,
      "y": 7,
      "z": 10,
      "name": "Rock_Shale_Brick"
    },
    {
      "x": -11,
      "y": 8,
      "z": 10,
      "name": "Rock_Shale_Brick"
    },
    {
      "x": -11,
      "y": 9,
      "z": 10,
      "name": "Rock_Shale_Brick"
    },
    {
      "x": -11,
      "y": 0,
      "z": 11,
      "name": "Rock_Shale_Brick"
    },
    {
      "x": -11,
      "y": 1,
      "z": 11,
      "name": "Rock_Shale_Cobble"
    },
    {
      "x": -11,
      "y": 2,
      "z": 11,
      "name": "Rock_Shale_Cobble"
    },
    {
      "x": -11,
      "y": 3,
      "z": 11,
      "name": "Rock_Shale_Brick"
    },
    {
      "x": -11,
      "y": 4,
      "z": 11,
      "name": "Rock_Shale_Brick"
    },
    {
      "x": -11,
      "y": 5,
      "z": 11,
      "name": "Rock_Shale_Brick"
    },
    {
      "x": -11,
      "y": 6,
      "z": 11,
      "name": "Rock_Shale_Cobble"
    },
    {
      "x": -11,
      "y": 7,
      "z": 11,
      "name": "Rock_Shale_Cobble"
    },
    {
      "x": -11,
      "y": 8,
      "z": 11,
      "name": "Rock_Shale_Brick"
    },
    {
      "x": -11,
      "y": 9,
      "z": 11,
      "name": "Rock_Shale_Cobble"
    },
    {
      "x": -11,
      "y": 0,
      "z": 12,
      "name": "Rock_Shale_Brick"
    },
    {
      "x": -11,
      "y": 1,
      "z": 12,
      "name": "Rock_Shale_Brick"
    },
    {
      "x": -11,
      "y": 2,
      "z": 12,
      "name": "Rock_Shale_Brick"
    },
    {
      "x": -11,
      "y": 3,
      "z": 12,
      "name": "Rock_Shale_Brick"
    },
    {
      "x": -11,
      "y": 4,
      "z": 12,
      "name": "Rock_Shale_Brick"
    },
    {
      "x": -11,
      "y": 5,
      "z": 12,
      "name": "Rock_Shale_Brick"
    },
    {
      "x": -11,
      "y": 6,
      "z": 12,
      "name": "Rock_Shale_Cobble"
    },
    {
      "x": -11,
      "y": 7,
      "z": 12,
      "name": "Rock_Shale_Brick"
    },
    {
      "x": -11,
      "y": 8,
      "z": 12,
      "name": "Rock_Shale_Brick"
    },
    {
      "x": -11,
      "y": 9,
      "z": 12,
      "name": "Rock_Shale_Cobble"
    },
    {
      "x": -10,
      "y": 0,
      "z": -12,
      "name": "Rock_Shale_Brick"
    },
    {
      "x": -10,
      "y": 1,
      "z": -12,
      "name": "Rock_Shale_Brick"
    },
    {
      "x": -10,
      "y": 2,
      "z": -12,
      "name": "Rock_Shale_Brick"
    },
    {
      "x": -10,
      "y": 3,
      "z": -12,
      "name": "Rock_Shale_Brick"
    },
    {
      "x": -10,
      "y": 4,
      "z": -12,
      "name": "Rock_Shale_Brick"
    },
    {
      "x": -10,
      "y": 5,
      "z": -12,
      "name": "Rock_Shale_Brick"
    },
    {
      "x": -10,
      "y": 6,
      "z": -12,
      "name": "Rock_Shale_Cobble"
    },
    {
      "x": -10,
      "y": 7,
      "z": -12,
      "name": "Rock_Shale_Brick"
    },
    {
      "x": -10,
      "y": 8,
      "z": -12,
      "name": "Rock_Shale_Brick"
    },
    {
      "x": -10,
      "y": 9,
      "z": -12,
      "name": "Rock_Shale_Brick"
    },
    {
      "x": -10,
      "y": 0,
      "z": -11,
      "name": "Rock_Shale_Brick"
    },
    {
      "x": -10,
      "y": 1,
      "z": -11,
      "name": "Rock_Shale_Brick"
    },
    {
      "x": -10,
      "y": 2,
      "z": -11,
      "name": "Rock_Shale_Brick"
    },
    {
      "x": -10,
      "y": 3,
      "z": -11,
      "name": "Rock_Shale_Brick"
    },
    {
      "x": -10,
      "y": 4,
      "z": -11,
      "name": "Rock_Shale_Brick"
    },
    {
      "x": -10,
      "y": 5,
      "z": -11,
      "name": "Rock_Shale_Brick"
    },
    {
      "x": -10,
      "y": 6,
      "z": -11,
      "name": "Rock_Shale_Cobble"
    },
    {
      "x": -10,
      "y": 7,
      "z": -11,
      "name": "Rock_Shale_Brick"
    },
    {
      "x": -10,
      "y": 8,
      "z": -11,
      "name": "Rock_Shale_Brick"
    },
    {
      "x": -10,
      "y": 9,
      "z": -11,
      "name": "Rock_Shale_Brick"
    },
    {
      "x": -10,
      "y": 0,
      "z": -10,
      "name": "Rock_Shale_Brick"
    },
    {
      "x": -10,
      "y": 1,
      "z": -10,
      "name": "Rock_Shale_Brick_Pillar_Base"
    },
    {
      "x": -10,
      "y": 2,
      "z": -10,
      "name": "Rock_Shale_Brick_Pillar_Middle"
    },
    {
      "x": -10,
      "y": 3,
      "z": -10,
      "name": "Rock_Shale_Brick_Pillar_Middle",
      "rotation": 8
    },
    {
      "x": -10,
      "y": 4,
      "z": -10,
      "name": "Rock_Shale_Brick_Pillar_Middle",
      "rotation": 8
    },
    {
      "x": -10,
      "y": 5,
      "z": -10,
      "name": "Rock_Shale_Brick_Pillar_Middle",
      "rotation": 8
    },
    {
      "x": -10,
      "y": 6,
      "z": -10,
      "name": "Rock_Shale_Brick_Pillar_Middle",
      "rotation": 8
    },
    {
      "x": -10,
      "y": 7,
      "z": -10,
      "name": "Rock_Shale_Brick_Pillar_Middle",
      "rotation": 8
    },
    {
      "x": -10,
      "y": 8,
      "z": -10,
      "name": "Rock_Shale_Brick_Pillar_Base",
      "rotation": 8
    },
    {
      "x": -10,
      "y": 9,
      "z": -10,
      "name": "Rock_Shale_Cobble"
    },
    {
      "x": -10,
      "y": 0,
      "z": -9,
      "name": "Rock_Shale_Brick"
    },
    {
      "x": -10,
      "y": 1,
      "z": -9,
      "name": "Empty"
    },
    {
      "x": -10,
      "y": 2,
      "z": -9,
      "name": "Empty"
    },
    {
      "x": -10,
      "y": 3,
      "z": -9,
      "name": "Empty"
    },
    {
      "x": -10,
      "y": 4,
      "z": -9,
      "name": "Empty"
    },
    {
      "x": -10,
      "y": 5,
      "z": -9,
      "name": "Empty"
    },
    {
      "x": -10,
      "y": 6,
      "z": -9,
      "name": "Empty"
    },
    {
      "x": -10,
      "y": 7,
      "z": -9,
      "name": "Empty"
    },
    {
      "x": -10,
      "y": 8,
      "z": -9,
      "name": "Empty"
    },
    {
      "x": -10,
      "y": 9,
      "z": -9,
      "name": "Rock_Shale_Brick"
    },
    {
      "x": -10,
      "y": 0,
      "z": -8,
      "name": "Rock_Shale_Brick"
    },
    {
      "x": -10,
      "y": 1,
      "z": -8,
      "name": "Empty"
    },
    {
      "x": -10,
      "y": 2,
      "z": -8,
      "name": "Empty"
    },
    {
      "x": -10,
      "y": 3,
      "z": -8,
      "name": "Empty"
    },
    {
      "x": -10,
      "y": 4,
      "z": -8,
      "name": "Empty"
    },
    {
      "x": -10,
      "y": 5,
      "z": -8,
      "name": "Empty"
    },
    {
      "x": -10,
      "y": 6,
      "z": -8,
      "name": "Empty"
    },
    {
      "x": -10,
      "y": 7,
      "z": -8,
      "name": "Empty"
    },
    {
      "x": -10,
      "y": 8,
      "z": -8,
      "name": "Empty"
    },
    {
      "x": -10,
      "y": 9,
      "z": -8,
      "name": "Rock_Shale_Brick"
    },
    {
      "x": -10,
      "y": 0,
      "z": -7,
      "name": "Rock_Shale_Brick"
    },
    {
      "x": -10,
      "y": 1,
      "z": -7,
      "name": "Empty"
    },
    {
      "x": -10,
      "y": 2,
      "z": -7,
      "name": "Empty"
    },
    {
      "x": -10,
      "y": 3,
      "z": -7,
      "name": "Empty"
    },
    {
      "x": -10,
      "y": 4,
      "z": -7,
      "name": "Empty"
    },
    {
      "x": -10,
      "y": 5,
      "z": -7,
      "name": "Empty"
    },
    {
      "x": -10,
      "y": 6,
      "z": -7,
      "name": "Empty"
    },
    {
      "x": -10,
      "y": 7,
      "z": -7,
      "name": "Empty"
    },
    {
      "x": -10,
      "y": 8,
      "z": -7,
      "name": "Empty"
    },
    {
      "x": -10,
      "y": 9,
      "z": -7,
      "name": "Rock_Shale_Cobble"
    },
    {
      "x": -10,
      "y": 0,
      "z": -6,
      "name": "Rock_Shale_Brick"
    },
    {
      "x": -10,
      "y": 1,
      "z": -6,
      "name": "Rock_Shale_Brick_Pillar_Base"
    },
    {
      "x": -10,
      "y": 2,
      "z": -6,
      "name": "Rock_Shale_Brick_Pillar_Middle",
      "rotation": 8
    },
    {
      "x": -10,
      "y": 3,
      "z": -6,
      "name": "Rock_Shale_Brick_Pillar_Middle",
      "rotation": 8
    },
    {
      "x": -10,
      "y": 4,
      "z": -6,
      "name": "Rock_Shale_Brick_Pillar_Middle",
      "rotation": 8
    },
    {
      "x": -10,
      "y": 5,
      "z": -6,
      "name": "Rock_Shale_Brick_Pillar_Middle",
      "rotation": 8
    },
    {
      "x": -10,
      "y": 6,
      "z": -6,
      "name": "Rock_Shale_Brick_Pillar_Middle",
      "rotation": 8
    },
    {
      "x": -10,
      "y": 7,
      "z": -6,
      "name": "Rock_Shale_Brick_Pillar_Middle",
      "rotation": 8
    },
    {
      "x": -10,
      "y": 8,
      "z": -6,
      "name": "Rock_Shale_Brick_Pillar_Base",
      "rotation": 8
    },
    {
      "x": -10,
      "y": 9,
      "z": -6,
      "name": "Rock_Shale_Brick"
    },
    {
      "x": -10,
      "y": 0,
      "z": -5,
      "name": "Rock_Shale_Brick"
    },
    {
      "x": -10,
      "y": 1,
      "z": -5,
      "name": "Empty"
    },
    {
      "x": -10,
      "y": 2,
      "z": -5,
      "name": "Empty"
    },
    {
      "x": -10,
      "y": 3,
      "z": -5,
      "name": "Empty"
    },
    {
      "x": -10,
      "y": 4,
      "z": -5,
      "name": "Empty"
    },
    {
      "x": -10,
      "y": 5,
      "z": -5,
      "name": "Empty"
    },
    {
      "x": -10,
      "y": 6,
      "z": -5,
      "name": "Empty"
    },
    {
      "x": -10,
      "y": 7,
      "z": -5,
      "name": "Empty"
    },
    {
      "x": -10,
      "y": 8,
      "z": -5,
      "name": "Empty"
    },
    {
      "x": -10,
      "y": 9,
      "z": -5,
      "name": "Rock_Shale_Brick"
    },
    {
      "x": -10,
      "y": 0,
      "z": -4,
      "name": "Rock_Shale_Cobble"
    },
    {
      "x": -10,
      "y": 1,
      "z": -4,
      "name": "Empty"
    },
    {
      "x": -10,
      "y": 2,
      "z": -4,
      "name": "Empty"
    },
    {
      "x": -10,
      "y": 3,
      "z": -4,
      "name": "Empty"
    },
    {
      "x": -10,
      "y": 4,
      "z": -4,
      "name": "Empty"
    },
    {
      "x": -10,
      "y": 5,
      "z": -4,
      "name": "Empty"
    },
    {
      "x": -10,
      "y": 6,
      "z": -4,
      "name": "Empty"
    },
    {
      "x": -10,
      "y": 7,
      "z": -4,
      "name": "Empty"
    },
    {
      "x": -10,
      "y": 8,
      "z": -4,
      "name": "Empty"
    },
    {
      "x": -10,
      "y": 9,
      "z": -4,
      "name": "Rock_Shale_Brick"
    },
    {
      "x": -10,
      "y": 0,
      "z": -3,
      "name": "Rock_Shale_Brick"
    },
    {
      "x": -10,
      "y": 1,
      "z": -3,
      "name": "Rubble_Shale",
      "support": 15
    },
    {
      "x": -10,
      "y": 2,
      "z": -3,
      "name": "Empty"
    },
    {
      "x": -10,
      "y": 3,
      "z": -3,
      "name": "Empty"
    },
    {
      "x": -10,
      "y": 4,
      "z": -3,
      "name": "Empty"
    },
    {
      "x": -10,
      "y": 5,
      "z": -3,
      "name": "Empty"
    },
    {
      "x": -10,
      "y": 6,
      "z": -3,
      "name": "Empty"
    },
    {
      "x": -10,
      "y": 7,
      "z": -3,
      "name": "Empty"
    },
    {
      "x": -10,
      "y": 8,
      "z": -3,
      "name": "Empty"
    },
    {
      "x": -10,
      "y": 9,
      "z": -3,
      "name": "Rock_Shale_Brick"
    },
    {
      "x": -10,
      "y": 0,
      "z": -2,
      "name": "Rock_Shale_Brick"
    },
    {
      "x": -10,
      "y": 1,
      "z": -2,
      "name": "Rock_Shale_Brick_Pillar_Base"
    },
    {
      "x": -10,
      "y": 2,
      "z": -2,
      "name": "Rock_Shale_Brick_Pillar_Middle",
      "rotation": 8
    },
    {
      "x": -10,
      "y": 3,
      "z": -2,
      "name": "Rock_Shale_Brick_Pillar_Middle",
      "rotation": 8
    },
    {
      "x": -10,
      "y": 4,
      "z": -2,
      "name": "Rock_Shale_Brick_Pillar_Middle",
      "rotation": 8
    },
    {
      "x": -10,
      "y": 5,
      "z": -2,
      "name": "Rock_Shale_Brick_Pillar_Middle",
      "rotation": 8
    },
    {
      "x": -10,
      "y": 6,
      "z": -2,
      "name": "Rock_Shale_Brick_Pillar_Middle",
      "rotation": 8
    },
    {
      "x": -10,
      "y": 7,
      "z": -2,
      "name": "Rock_Shale_Brick_Pillar_Middle",
      "rotation": 8
    },
    {
      "x": -10,
      "y": 8,
      "z": -2,
      "name": "Rock_Shale_Brick_Pillar_Base",
      "rotation": 8
    },
    {
      "x": -10,
      "y": 9,
      "z": -2,
      "name": "Rock_Shale_Brick"
    },
    {
      "x": -10,
      "y": 0,
      "z": -1,
      "name": "Rock_Shale_Brick"
    },
    {
      "x": -10,
      "y": 1,
      "z": -1,
      "name": "Rubble_Shale_Medium",
      "support": 15
    },
    {
      "x": -10,
      "y": 2,
      "z": -1,
      "name": "Empty"
    },
    {
      "x": -10,
      "y": 3,
      "z": -1,
      "name": "Empty"
    },
    {
      "x": -10,
      "y": 4,
      "z": -1,
      "name": "Empty"
    },
    {
      "x": -10,
      "y": 5,
      "z": -1,
      "name": "Empty"
    },
    {
      "x": -10,
      "y": 6,
      "z": -1,
      "name": "Empty"
    },
    {
      "x": -10,
      "y": 7,
      "z": -1,
      "name": "Empty"
    },
    {
      "x": -10,
      "y": 8,
      "z": -1,
      "name": "Empty"
    },
    {
      "x": -10,
      "y": 9,
      "z": -1,
      "name": "Rock_Shale_Brick"
    },
    {
      "x": -10,
      "y": 0,
      "z": 0,
      "name": "Rock_Shale_Brick"
    },
    {
      "x": -10,
      "y": 1,
      "z": 0,
      "name": "Empty"
    },
    {
      "x": -10,
      "y": 2,
      "z": 0,
      "name": "Empty"
    },
    {
      "x": -10,
      "y": 3,
      "z": 0,
      "name": "Empty"
    },
    {
      "x": -10,
      "y": 4,
      "z": 0,
      "name": "Empty"
    },
    {
      "x": -10,
      "y": 5,
      "z": 0,
      "name": "Empty"
    },
    {
      "x": -10,
      "y": 6,
      "z": 0,
      "name": "Empty"
    },
    {
      "x": -10,
      "y": 7,
      "z": 0,
      "name": "Empty"
    },
    {
      "x": -10,
      "y": 8,
      "z": 0,
      "name": "Empty"
    },
    {
      "x": -10,
      "y": 9,
      "z": 0,
      "name": "Rock_Shale_Brick"
    },
    {
      "x": -10,
      "y": 0,
      "z": 1,
      "name": "Rock_Shale_Cobble"
    },
    {
      "x": -10,
      "y": 1,
      "z": 1,
      "name": "Empty"
    },
    {
      "x": -10,
      "y": 2,
      "z": 1,
      "name": "Empty"
    },
    {
      "x": -10,
      "y": 3,
      "z": 1,
      "name": "Empty"
    },
    {
      "x": -10,
      "y": 4,
      "z": 1,
      "name": "Empty"
    },
    {
      "x": -10,
      "y": 5,
      "z": 1,
      "name": "Empty"
    },
    {
      "x": -10,
      "y": 6,
      "z": 1,
      "name": "Empty"
    },
    {
      "x": -10,
      "y": 7,
      "z": 1,
      "name": "Empty"
    },
    {
      "x": -10,
      "y": 8,
      "z": 1,
      "name": "Empty"
    },
    {
      "x": -10,
      "y": 9,
      "z": 1,
      "name": "Rock_Shale_Brick"
    },
    {
      "x": -10,
      "y": 0,
      "z": 2,
      "name": "Rock_Shale_Brick"
    },
    {
      "x": -10,
      "y": 1,
      "z": 2,
      "name": "Rock_Shale_Brick_Pillar_Base"
    },
    {
      "x": -10,
      "y": 2,
      "z": 2,
      "name": "Rock_Shale_Brick_Pillar_Middle"
    },
    {
      "x": -10,
      "y": 3,
      "z": 2,
      "name": "Rock_Shale_Brick_Pillar_Middle",
      "rotation": 8
    },
    {
      "x": -10,
      "y": 4,
      "z": 2,
      "name": "Rock_Shale_Brick_Pillar_Middle",
      "rotation": 8
    },
    {
      "x": -10,
      "y": 5,
      "z": 2,
      "name": "Rock_Shale_Brick_Pillar_Middle",
      "rotation": 8
    },
    {
      "x": -10,
      "y": 6,
      "z": 2,
      "name": "Rock_Shale_Brick_Pillar_Middle",
      "rotation": 8
    },
    {
      "x": -10,
      "y": 7,
      "z": 2,
      "name": "Rock_Shale_Brick_Pillar_Middle",
      "rotation": 8
    },
    {
      "x": -10,
      "y": 8,
      "z": 2,
      "name": "Rock_Shale_Brick_Pillar_Base",
      "rotation": 8
    },
    {
      "x": -10,
      "y": 9,
      "z": 2,
      "name": "Rock_Shale_Brick"
    },
    {
      "x": -10,
      "y": 0,
      "z": 3,
      "name": "Rock_Shale_Brick"
    },
    {
      "x": -10,
      "y": 1,
      "z": 3,
      "name": "Empty"
    },
    {
      "x": -10,
      "y": 2,
      "z": 3,
      "name": "Empty"
    },
    {
      "x": -10,
      "y": 3,
      "z": 3,
      "name": "Empty"
    },
    {
      "x": -10,
      "y": 4,
      "z": 3,
      "name": "Empty"
    },
    {
      "x": -10,
      "y": 5,
      "z": 3,
      "name": "Empty"
    },
    {
      "x": -10,
      "y": 6,
      "z": 3,
      "name": "Empty"
    },
    {
      "x": -10,
      "y": 7,
      "z": 3,
      "name": "Empty"
    },
    {
      "x": -10,
      "y": 8,
      "z": 3,
      "name": "Empty"
    },
    {
      "x": -10,
      "y": 9,
      "z": 3,
      "name": "Rock_Shale_Brick"
    },
    {
      "x": -10,
      "y": 0,
      "z": 4,
      "name": "Rock_Shale_Brick"
    },
    {
      "x": -10,
      "y": 1,
      "z": 4,
      "name": "Empty"
    },
    {
      "x": -10,
      "y": 2,
      "z": 4,
      "name": "Empty"
    },
    {
      "x": -10,
      "y": 3,
      "z": 4,
      "name": "Empty"
    },
    {
      "x": -10,
      "y": 4,
      "z": 4,
      "name": "Empty"
    },
    {
      "x": -10,
      "y": 5,
      "z": 4,
      "name": "Empty"
    },
    {
      "x": -10,
      "y": 6,
      "z": 4,
      "name": "Empty"
    },
    {
      "x": -10,
      "y": 7,
      "z": 4,
      "name": "Empty"
    },
    {
      "x": -10,
      "y": 8,
      "z": 4,
      "name": "Empty"
    },
    {
      "x": -10,
      "y": 9,
      "z": 4,
      "name": "Rock_Shale_Brick"
    },
    {
      "x": -10,
      "y": 0,
      "z": 5,
      "name": "Rock_Shale_Brick"
    },
    {
      "x": -10,
      "y": 1,
      "z": 5,
      "name": "Empty"
    },
    {
      "x": -10,
      "y": 2,
      "z": 5,
      "name": "Empty"
    },
    {
      "x": -10,
      "y": 3,
      "z": 5,
      "name": "Empty"
    },
    {
      "x": -10,
      "y": 4,
      "z": 5,
      "name": "Empty"
    },
    {
      "x": -10,
      "y": 5,
      "z": 5,
      "name": "Empty"
    },
    {
      "x": -10,
      "y": 6,
      "z": 5,
      "name": "Empty"
    },
    {
      "x": -10,
      "y": 7,
      "z": 5,
      "name": "Empty"
    },
    {
      "x": -10,
      "y": 8,
      "z": 5,
      "name": "Empty"
    },
    {
      "x": -10,
      "y": 9,
      "z": 5,
      "name": "Rock_Shale_Brick"
    },
    {
      "x": -10,
      "y": 0,
      "z": 6,
      "name": "Rock_Shale_Brick"
    },
    {
      "x": -10,
      "y": 1,
      "z": 6,
      "name": "Rock_Shale_Brick_Pillar_Base"
    },
    {
      "x": -10,
      "y": 2,
      "z": 6,
      "name": "Rock_Shale_Brick_Pillar_Middle",
      "rotation": 8
    },
    {
      "x": -10,
      "y": 3,
      "z": 6,
      "name": "Rock_Shale_Brick_Pillar_Middle",
      "rotation": 8
    },
    {
      "x": -10,
      "y": 4,
      "z": 6,
      "name": "Rock_Shale_Brick_Pillar_Middle",
      "rotation": 8
    },
    {
      "x": -10,
      "y": 5,
      "z": 6,
      "name": "Rock_Shale_Brick_Pillar_Middle",
      "rotation": 8
    },
    {
      "x": -10,
      "y": 6,
      "z": 6,
      "name": "Rock_Shale_Brick_Pillar_Middle",
      "rotation": 8
    },
    {
      "x": -10,
      "y": 7,
      "z": 6,
      "name": "Rock_Shale_Brick_Pillar_Middle",
      "rotation": 8
    },
    {
      "x": -10,
      "y": 8,
      "z": 6,
      "name": "Rock_Shale_Brick_Pillar_Base",
      "rotation": 8
    },
    {
      "x": -10,
      "y": 9,
      "z": 6,
      "name": "Rock_Shale_Brick"
    },
    {
      "x": -10,
      "y": 0,
      "z": 7,
      "name": "Rock_Shale_Cobble"
    },
    {
      "x": -10,
      "y": 1,
      "z": 7,
      "name": "Empty"
    },
    {
      "x": -10,
      "y": 2,
      "z": 7,
      "name": "Empty"
    },
    {
      "x": -10,
      "y": 3,
      "z": 7,
      "name": "Empty"
    },
    {
      "x": -10,
      "y": 4,
      "z": 7,
      "name": "Empty"
    },
    {
      "x": -10,
      "y": 5,
      "z": 7,
      "name": "Empty"
    },
    {
      "x": -10,
      "y": 6,
      "z": 7,
      "name": "Empty"
    },
    {
      "x": -10,
      "y": 7,
      "z": 7,
      "name": "Empty"
    },
    {
      "x": -10,
      "y": 8,
      "z": 7,
      "name": "Empty"
    },
    {
      "x": -10,
      "y": 9,
      "z": 7,
      "name": "Rock_Shale_Brick"
    },
    {
      "x": -10,
      "y": 0,
      "z": 8,
      "name": "Rock_Shale_Brick"
    },
    {
      "x": -10,
      "y": 1,
      "z": 8,
      "name": "Empty"
    },
    {
      "x": -10,
      "y": 2,
      "z": 8,
      "name": "Empty"
    },
    {
      "x": -10,
      "y": 3,
      "z": 8,
      "name": "Empty"
    },
    {
      "x": -10,
      "y": 4,
      "z": 8,
      "name": "Empty"
    },
    {
      "x": -10,
      "y": 5,
      "z": 8,
      "name": "Empty"
    },
    {
      "x": -10,
      "y": 6,
      "z": 8,
      "name": "Empty"
    },
    {
      "x": -10,
      "y": 7,
      "z": 8,
      "name": "Empty"
    },
    {
      "x": -10,
      "y": 8,
      "z": 8,
      "name": "Empty"
    },
    {
      "x": -10,
      "y": 9,
      "z": 8,
      "name": "Rock_Shale_Brick"
    },
    {
      "x": -10,
      "y": 0,
      "z": 9,
      "name": "Rock_Shale_Cobble"
    },
    {
      "x": -10,
      "y": 1,
      "z": 9,
      "name": "Empty"
    },
    {
      "x": -10,
      "y": 2,
      "z": 9,
      "name": "Empty"
    },
    {
      "x": -10,
      "y": 3,
      "z": 9,
      "name": "Empty"
    },
    {
      "x": -10,
      "y": 4,
      "z": 9,
      "name": "Empty"
    },
    {
      "x": -10,
      "y": 5,
      "z": 9,
      "name": "Empty"
    },
    {
      "x": -10,
      "y": 6,
      "z": 9,
      "name": "Empty"
    },
    {
      "x": -10,
      "y": 7,
      "z": 9,
      "name": "Empty"
    },
    {
      "x": -10,
      "y": 8,
      "z": 9,
      "name": "Empty"
    },
    {
      "x": -10,
      "y": 9,
      "z": 9,
      "name": "Rock_Shale_Brick"
    },
    {
      "x": -10,
      "y": 0,
      "z": 10,
      "name": "Rock_Shale_Brick"
    },
    {
      "x": -10,
      "y": 1,
      "z": 10,
      "name": "Rock_Shale_Brick_Pillar_Base"
    },
    {
      "x": -10,
      "y": 2,
      "z": 10,
      "name": "Rock_Shale_Brick_Pillar_Middle",
      "rotation": 8
    },
    {
      "x": -10,
      "y": 3,
      "z": 10,
      "name": "Rock_Shale_Brick_Pillar_Middle",
      "rotation": 8
    },
    {
      "x": -10,
      "y": 4,
      "z": 10,
      "name": "Rock_Shale_Brick_Pillar_Middle",
      "rotation": 8
    },
    {
      "x": -10,
      "y": 5,
      "z": 10,
      "name": "Rock_Shale_Brick_Pillar_Middle",
      "rotation": 8
    },
    {
      "x": -10,
      "y": 6,
      "z": 10,
      "name": "Rock_Shale_Brick_Pillar_Middle",
      "rotation": 8
    },
    {
      "x": -10,
      "y": 7,
      "z": 10,
      "name": "Rock_Shale_Brick_Pillar_Middle",
      "rotation": 8
    },
    {
      "x": -10,
      "y": 8,
      "z": 10,
      "name": "Rock_Shale_Brick_Pillar_Base",
      "rotation": 8
    },
    {
      "x": -10,
      "y": 9,
      "z": 10,
      "name": "Rock_Shale_Brick"
    },
    {
      "x": -10,
      "y": 0,
      "z": 11,
      "name": "Rock_Shale_Brick"
    },
    {
      "x": -10,
      "y": 1,
      "z": 11,
      "name": "Rock_Shale_Brick"
    },
    {
      "x": -10,
      "y": 2,
      "z": 11,
      "name": "Rock_Shale_Brick"
    },
    {
      "x": -10,
      "y": 3,
      "z": 11,
      "name": "Rock_Shale_Brick"
    },
    {
      "x": -10,
      "y": 4,
      "z": 11,
      "name": "Rock_Shale_Brick"
    },
    {
      "x": -10,
      "y": 5,
      "z": 11,
      "name": "Rock_Shale_Brick"
    },
    {
      "x": -10,
      "y": 6,
      "z": 11,
      "name": "Rock_Shale_Brick"
    },
    {
      "x": -10,
      "y": 7,
      "z": 11,
      "name": "Rock_Shale_Cobble"
    },
    {
      "x": -10,
      "y": 8,
      "z": 11,
      "name": "Rock_Shale_Brick"
    },
    {
      "x": -10,
      "y": 9,
      "z": 11,
      "name": "Rock_Shale_Cobble"
    },
    {
      "x": -10,
      "y": 0,
      "z": 12,
      "name": "Rock_Shale_Cobble"
    },
    {
      "x": -10,
      "y": 1,
      "z": 12,
      "name": "Rock_Shale_Brick"
    },
    {
      "x": -10,
      "y": 2,
      "z": 12,
      "name": "Rock_Shale_Cobble"
    },
    {
      "x": -10,
      "y": 3,
      "z": 12,
      "name": "Rock_Shale_Brick"
    },
    {
      "x": -10,
      "y": 4,
      "z": 12,
      "name": "Rock_Shale_Brick"
    },
    {
      "x": -10,
      "y": 5,
      "z": 12,
      "name": "Rock_Shale_Brick"
    },
    {
      "x": -10,
      "y": 6,
      "z": 12,
      "name": "Rock_Shale_Brick"
    },
    {
      "x": -10,
      "y": 7,
      "z": 12,
      "name": "Rock_Shale_Cobble"
    },
    {
      "x": -10,
      "y": 8,
      "z": 12,
      "name": "Rock_Shale_Brick"
    },
    {
      "x": -10,
      "y": 9,
      "z": 12,
      "name": "Rock_Shale_Cobble"
    },
    {
      "x": -9,
      "y": 0,
      "z": -12,
      "name": "Rock_Shale_Brick"
    },
    {
      "x": -9,
      "y": 1,
      "z": -12,
      "name": "Rock_Shale_Brick"
    },
    {
      "x": -9,
      "y": 2,
      "z": -12,
      "name": "Rock_Shale_Cobble"
    },
    {
      "x": -9,
      "y": 3,
      "z": -12,
      "name": "Rock_Shale_Brick"
    },
    {
      "x": -9,
      "y": 4,
      "z": -12,
      "name": "Rock_Shale_Cobble"
    },
    {
      "x": -9,
      "y": 5,
      "z": -12,
      "name": "Rock_Shale_Brick"
    },
    {
      "x": -9,
      "y": 6,
      "z": -12,
      "name": "Rock_Shale_Brick"
    },
    {
      "x": -9,
      "y": 7,
      "z": -12,
      "name": "Rock_Shale_Cobble"
    },
    {
      "x": -9,
      "y": 8,
      "z": -12,
      "name": "Rock_Shale_Cobble"
    },
    {
      "x": -9,
      "y": 9,
      "z": -12,
      "name": "Rock_Shale_Cobble"
    },
    {
      "x": -9,
      "y": 0,
      "z": -11,
      "name": "Rock_Shale_Brick"
    },
    {
      "x": -9,
      "y": 1,
      "z": -11,
      "name": "Rock_Shale_Brick"
    },
    {
      "x": -9,
      "y": 2,
      "z": -11,
      "name": "Rock_Shale_Brick"
    },
    {
      "x": -9,
      "y": 3,
      "z": -11,
      "name": "Rock_Shale_Brick"
    },
    {
      "x": -9,
      "y": 4,
      "z": -11,
      "name": "Rock_Shale_Brick"
    },
    {
      "x": -9,
      "y": 5,
      "z": -11,
      "name": "Rock_Shale_Brick"
    },
    {
      "x": -9,
      "y": 6,
      "z": -11,
      "name": "Rock_Shale_Brick"
    },
    {
      "x": -9,
      "y": 7,
      "z": -11,
      "name": "Rock_Shale_Brick"
    },
    {
      "x": -9,
      "y": 8,
      "z": -11,
      "name": "Rock_Shale_Brick"
    },
    {
      "x": -9,
      "y": 9,
      "z": -11,
      "name": "Rock_Shale_Brick"
    },
    {
      "x": -9,
      "y": 0,
      "z": -10,
      "name": "Rock_Shale_Brick"
    },
    {
      "x": -9,
      "y": 1,
      "z": -10,
      "name": "Empty"
    },
    {
      "x": -9,
      "y": 2,
      "z": -10,
      "name": "Empty"
    },
    {
      "x": -9,
      "y": 3,
      "z": -10,
      "name": "Empty"
    },
    {
      "x": -9,
      "y": 4,
      "z": -10,
      "name": "Empty"
    },
    {
      "x": -9,
      "y": 5,
      "z": -10,
      "name": "Empty"
    },
    {
      "x": -9,
      "y": 6,
      "z": -10,
      "name": "Empty"
    },
    {
      "x": -9,
      "y": 7,
      "z": -10,
      "name": "Empty"
    },
    {
      "x": -9,
      "y": 8,
      "z": -10,
      "name": "Empty"
    },
    {
      "x": -9,
      "y": 9,
      "z": -10,
      "name": "Rock_Shale_Brick"
    },
    {
      "x": -9,
      "y": 0,
      "z": -9,
      "name": "Rock_Shale_Brick"
    },
    {
      "x": -9,
      "y": 1,
      "z": -9,
      "name": "Empty"
    },
    {
      "x": -9,
      "y": 2,
      "z": -9,
      "name": "Empty"
    },
    {
      "x": -9,
      "y": 3,
      "z": -9,
      "name": "Empty"
    },
    {
      "x": -9,
      "y": 4,
      "z": -9,
      "name": "Empty"
    },
    {
      "x": -9,
      "y": 5,
      "z": -9,
      "name": "Empty"
    },
    {
      "x": -9,
      "y": 6,
      "z": -9,
      "name": "Empty"
    },
    {
      "x": -9,
      "y": 7,
      "z": -9,
      "name": "Empty"
    },
    {
      "x": -9,
      "y": 8,
      "z": -9,
      "name": "Empty"
    },
    {
      "x": -9,
      "y": 9,
      "z": -9,
      "name": "Rock_Shale_Brick"
    },
    {
      "x": -9,
      "y": 0,
      "z": -8,
      "name": "Rock_Shale_Brick"
    },
    {
      "x": -9,
      "y": 1,
      "z": -8,
      "name": "Empty"
    },
    {
      "x": -9,
      "y": 2,
      "z": -8,
      "name": "Empty"
    },
    {
      "x": -9,
      "y": 3,
      "z": -8,
      "name": "Empty"
    },
    {
      "x": -9,
      "y": 4,
      "z": -8,
      "name": "Empty"
    },
    {
      "x": -9,
      "y": 5,
      "z": -8,
      "name": "Empty"
    },
    {
      "x": -9,
      "y": 6,
      "z": -8,
      "name": "Empty"
    },
    {
      "x": -9,
      "y": 7,
      "z": -8,
      "name": "Empty"
    },
    {
      "x": -9,
      "y": 8,
      "z": -8,
      "name": "Empty"
    },
    {
      "x": -9,
      "y": 9,
      "z": -8,
      "name": "Rock_Shale_Cobble"
    },
    {
      "x": -9,
      "y": 0,
      "z": -7,
      "name": "Rock_Shale_Brick"
    },
    {
      "x": -9,
      "y": 1,
      "z": -7,
      "name": "Empty"
    },
    {
      "x": -9,
      "y": 2,
      "z": -7,
      "name": "Empty"
    },
    {
      "x": -9,
      "y": 3,
      "z": -7,
      "name": "Empty"
    },
    {
      "x": -9,
      "y": 4,
      "z": -7,
      "name": "Empty"
    },
    {
      "x": -9,
      "y": 5,
      "z": -7,
      "name": "Empty"
    },
    {
      "x": -9,
      "y": 6,
      "z": -7,
      "name": "Empty"
    },
    {
      "x": -9,
      "y": 7,
      "z": -7,
      "name": "Empty"
    },
    {
      "x": -9,
      "y": 8,
      "z": -7,
      "name": "Empty"
    },
    {
      "x": -9,
      "y": 9,
      "z": -7,
      "name": "Rock_Shale_Brick"
    },
    {
      "x": -9,
      "y": 0,
      "z": -6,
      "name": "Rock_Shale_Brick"
    },
    {
      "x": -9,
      "y": 1,
      "z": -6,
      "name": "Empty"
    },
    {
      "x": -9,
      "y": 2,
      "z": -6,
      "name": "Empty"
    },
    {
      "x": -9,
      "y": 3,
      "z": -6,
      "name": "Empty"
    },
    {
      "x": -9,
      "y": 4,
      "z": -6,
      "name": "Empty"
    },
    {
      "x": -9,
      "y": 5,
      "z": -6,
      "name": "Empty"
    },
    {
      "x": -9,
      "y": 6,
      "z": -6,
      "name": "Empty"
    },
    {
      "x": -9,
      "y": 7,
      "z": -6,
      "name": "Empty"
    },
    {
      "x": -9,
      "y": 8,
      "z": -6,
      "name": "Empty"
    },
    {
      "x": -9,
      "y": 9,
      "z": -6,
      "name": "Rock_Shale_Brick"
    },
    {
      "x": -9,
      "y": 0,
      "z": -5,
      "name": "Rock_Shale_Brick"
    },
    {
      "x": -9,
      "y": 1,
      "z": -5,
      "name": "Empty"
    },
    {
      "x": -9,
      "y": 2,
      "z": -5,
      "name": "Empty"
    },
    {
      "x": -9,
      "y": 3,
      "z": -5,
      "name": "Empty"
    },
    {
      "x": -9,
      "y": 4,
      "z": -5,
      "name": "Empty"
    },
    {
      "x": -9,
      "y": 5,
      "z": -5,
      "name": "Empty"
    },
    {
      "x": -9,
      "y": 6,
      "z": -5,
      "name": "Empty"
    },
    {
      "x": -9,
      "y": 7,
      "z": -5,
      "name": "Empty"
    },
    {
      "x": -9,
      "y": 8,
      "z": -5,
      "name": "Empty"
    },
    {
      "x": -9,
      "y": 9,
      "z": -5,
      "name": "Rock_Shale_Brick"
    },
    {
      "x": -9,
      "y": 0,
      "z": -4,
      "name": "Rock_Shale_Brick"
    },
    {
      "x": -9,
      "y": 1,
      "z": -4,
      "name": "Empty"
    },
    {
      "x": -9,
      "y": 2,
      "z": -4,
      "name": "Empty"
    },
    {
      "x": -9,
      "y": 3,
      "z": -4,
      "name": "Empty"
    },
    {
      "x": -9,
      "y": 4,
      "z": -4,
      "name": "Empty"
    },
    {
      "x": -9,
      "y": 5,
      "z": -4,
      "name": "Empty"
    },
    {
      "x": -9,
      "y": 6,
      "z": -4,
      "name": "Empty"
    },
    {
      "x": -9,
      "y": 7,
      "z": -4,
      "name": "Empty"
    },
    {
      "x": -9,
      "y": 8,
      "z": -4,
      "name": "Empty"
    },
    {
      "x": -9,
      "y": 9,
      "z": -4,
      "name": "Rock_Shale_Brick"
    },
    {
      "x": -9,
      "y": 0,
      "z": -3,
      "name": "Rock_Shale_Brick"
    },
    {
      "x": -9,
      "y": 1,
      "z": -3,
      "name": "Empty"
    },
    {
      "x": -9,
      "y": 2,
      "z": -3,
      "name": "Empty"
    },
    {
      "x": -9,
      "y": 3,
      "z": -3,
      "name": "Empty"
    },
    {
      "x": -9,
      "y": 4,
      "z": -3,
      "name": "Empty"
    },
    {
      "x": -9,
      "y": 5,
      "z": -3,
      "name": "Empty"
    },
    {
      "x": -9,
      "y": 6,
      "z": -3,
      "name": "Empty"
    },
    {
      "x": -9,
      "y": 7,
      "z": -3,
      "name": "Empty"
    },
    {
      "x": -9,
      "y": 8,
      "z": -3,
      "name": "Empty"
    },
    {
      "x": -9,
      "y": 9,
      "z": -3,
      "name": "Rock_Shale_Brick"
    },
    {
      "x": -9,
      "y": 0,
      "z": -2,
      "name": "Rock_Shale_Brick"
    },
    {
      "x": -9,
      "y": 1,
      "z": -2,
      "name": "Empty"
    },
    {
      "x": -9,
      "y": 2,
      "z": -2,
      "name": "Empty"
    },
    {
      "x": -9,
      "y": 3,
      "z": -2,
      "name": "Empty"
    },
    {
      "x": -9,
      "y": 4,
      "z": -2,
      "name": "Empty"
    },
    {
      "x": -9,
      "y": 5,
      "z": -2,
      "name": "Empty"
    },
    {
      "x": -9,
      "y": 6,
      "z": -2,
      "name": "Empty"
    },
    {
      "x": -9,
      "y": 7,
      "z": -2,
      "name": "Empty"
    },
    {
      "x": -9,
      "y": 8,
      "z": -2,
      "name": "Empty"
    },
    {
      "x": -9,
      "y": 9,
      "z": -2,
      "name": "Rock_Shale_Cobble"
    },
    {
      "x": -9,
      "y": 0,
      "z": -1,
      "name": "Rock_Shale_Cobble"
    },
    {
      "x": -9,
      "y": 1,
      "z": -1,
      "name": "Empty"
    },
    {
      "x": -9,
      "y": 2,
      "z": -1,
      "name": "Empty"
    },
    {
      "x": -9,
      "y": 3,
      "z": -1,
      "name": "Empty"
    },
    {
      "x": -9,
      "y": 4,
      "z": -1,
      "name": "Empty"
    },
    {
      "x": -9,
      "y": 5,
      "z": -1,
      "name": "Empty"
    },
    {
      "x": -9,
      "y": 6,
      "z": -1,
      "name": "Empty"
    },
    {
      "x": -9,
      "y": 7,
      "z": -1,
      "name": "Empty"
    },
    {
      "x": -9,
      "y": 8,
      "z": -1,
      "name": "Empty"
    },
    {
      "x": -9,
      "y": 9,
      "z": -1,
      "name": "Rock_Shale_Brick"
    },
    {
      "x": -9,
      "y": 0,
      "z": 0,
      "name": "Rock_Shale_Brick"
    },
    {
      "x": -9,
      "y": 1,
      "z": 0,
      "name": "Empty"
    },
    {
      "x": -9,
      "y": 2,
      "z": 0,
      "name": "Empty"
    },
    {
      "x": -9,
      "y": 3,
      "z": 0,
      "name": "Empty"
    },
    {
      "x": -9,
      "y": 4,
      "z": 0,
      "name": "Empty"
    },
    {
      "x": -9,
      "y": 5,
      "z": 0,
      "name": "Empty"
    },
    {
      "x": -9,
      "y": 6,
      "z": 0,
      "name": "Empty"
    },
    {
      "x": -9,
      "y": 7,
      "z": 0,
      "name": "Empty"
    },
    {
      "x": -9,
      "y": 8,
      "z": 0,
      "name": "Empty"
    },
    {
      "x": -9,
      "y": 9,
      "z": 0,
      "name": "Rock_Shale_Brick"
    },
    {
      "x": -9,
      "y": 0,
      "z": 1,
      "name": "Rock_Shale_Brick"
    },
    {
      "x": -9,
      "y": 1,
      "z": 1,
      "name": "Empty"
    },
    {
      "x": -9,
      "y": 2,
      "z": 1,
      "name": "Empty"
    },
    {
      "x": -9,
      "y": 3,
      "z": 1,
      "name": "Empty"
    },
    {
      "x": -9,
      "y": 4,
      "z": 1,
      "name": "Empty"
    },
    {
      "x": -9,
      "y": 5,
      "z": 1,
      "name": "Empty"
    },
    {
      "x": -9,
      "y": 6,
      "z": 1,
      "name": "Empty"
    },
    {
      "x": -9,
      "y": 7,
      "z": 1,
      "name": "Empty"
    },
    {
      "x": -9,
      "y": 8,
      "z": 1,
      "name": "Empty"
    },
    {
      "x": -9,
      "y": 9,
      "z": 1,
      "name": "Rock_Shale_Brick"
    },
    {
      "x": -9,
      "y": 0,
      "z": 2,
      "name": "Rock_Shale_Brick"
    },
    {
      "x": -9,
      "y": 1,
      "z": 2,
      "name": "Empty"
    },
    {
      "x": -9,
      "y": 2,
      "z": 2,
      "name": "Empty"
    },
    {
      "x": -9,
      "y": 3,
      "z": 2,
      "name": "Empty"
    },
    {
      "x": -9,
      "y": 4,
      "z": 2,
      "name": "Empty"
    },
    {
      "x": -9,
      "y": 5,
      "z": 2,
      "name": "Empty"
    },
    {
      "x": -9,
      "y": 6,
      "z": 2,
      "name": "Empty"
    },
    {
      "x": -9,
      "y": 7,
      "z": 2,
      "name": "Empty"
    },
    {
      "x": -9,
      "y": 8,
      "z": 2,
      "name": "Empty"
    },
    {
      "x": -9,
      "y": 9,
      "z": 2,
      "name": "Rock_Shale_Brick"
    },
    {
      "x": -9,
      "y": 0,
      "z": 3,
      "name": "Rock_Shale_Brick"
    },
    {
      "x": -9,
      "y": 1,
      "z": 3,
      "name": "Empty"
    },
    {
      "x": -9,
      "y": 2,
      "z": 3,
      "name": "Empty"
    },
    {
      "x": -9,
      "y": 3,
      "z": 3,
      "name": "Empty"
    },
    {
      "x": -9,
      "y": 4,
      "z": 3,
      "name": "Empty"
    },
    {
      "x": -9,
      "y": 5,
      "z": 3,
      "name": "Empty"
    },
    {
      "x": -9,
      "y": 6,
      "z": 3,
      "name": "Empty"
    },
    {
      "x": -9,
      "y": 7,
      "z": 3,
      "name": "Empty"
    },
    {
      "x": -9,
      "y": 8,
      "z": 3,
      "name": "Empty"
    },
    {
      "x": -9,
      "y": 9,
      "z": 3,
      "name": "Rock_Shale_Brick"
    },
    {
      "x": -9,
      "y": 0,
      "z": 4,
      "name": "Rock_Shale_Brick"
    },
    {
      "x": -9,
      "y": 1,
      "z": 4,
      "name": "Empty"
    },
    {
      "x": -9,
      "y": 2,
      "z": 4,
      "name": "Empty"
    },
    {
      "x": -9,
      "y": 3,
      "z": 4,
      "name": "Empty"
    },
    {
      "x": -9,
      "y": 4,
      "z": 4,
      "name": "Empty"
    },
    {
      "x": -9,
      "y": 5,
      "z": 4,
      "name": "Empty"
    },
    {
      "x": -9,
      "y": 6,
      "z": 4,
      "name": "Empty"
    },
    {
      "x": -9,
      "y": 7,
      "z": 4,
      "name": "Empty"
    },
    {
      "x": -9,
      "y": 8,
      "z": 4,
      "name": "Empty"
    },
    {
      "x": -9,
      "y": 9,
      "z": 4,
      "name": "Rock_Shale_Brick"
    },
    {
      "x": -9,
      "y": 0,
      "z": 5,
      "name": "Rock_Shale_Brick"
    },
    {
      "x": -9,
      "y": 1,
      "z": 5,
      "name": "Empty"
    },
    {
      "x": -9,
      "y": 2,
      "z": 5,
      "name": "Empty"
    },
    {
      "x": -9,
      "y": 3,
      "z": 5,
      "name": "Empty"
    },
    {
      "x": -9,
      "y": 4,
      "z": 5,
      "name": "Empty"
    },
    {
      "x": -9,
      "y": 5,
      "z": 5,
      "name": "Empty"
    },
    {
      "x": -9,
      "y": 6,
      "z": 5,
      "name": "Empty"
    },
    {
      "x": -9,
      "y": 7,
      "z": 5,
      "name": "Empty"
    },
    {
      "x": -9,
      "y": 8,
      "z": 5,
      "name": "Empty"
    },
    {
      "x": -9,
      "y": 9,
      "z": 5,
      "name": "Rock_Shale_Cobble"
    },
    {
      "x": -9,
      "y": 0,
      "z": 6,
      "name": "Rock_Shale_Brick"
    },
    {
      "x": -9,
      "y": 1,
      "z": 6,
      "name": "Empty"
    },
    {
      "x": -9,
      "y": 2,
      "z": 6,
      "name": "Empty"
    },
    {
      "x": -9,
      "y": 3,
      "z": 6,
      "name": "Empty"
    },
    {
      "x": -9,
      "y": 4,
      "z": 6,
      "name": "Empty"
    },
    {
      "x": -9,
      "y": 5,
      "z": 6,
      "name": "Empty"
    },
    {
      "x": -9,
      "y": 6,
      "z": 6,
      "name": "Empty"
    },
    {
      "x": -9,
      "y": 7,
      "z": 6,
      "name": "Empty"
    },
    {
      "x": -9,
      "y": 8,
      "z": 6,
      "name": "Empty"
    },
    {
      "x": -9,
      "y": 9,
      "z": 6,
      "name": "Rock_Shale_Brick"
    },
    {
      "x": -9,
      "y": 0,
      "z": 7,
      "name": "Rock_Shale_Brick"
    },
    {
      "x": -9,
      "y": 1,
      "z": 7,
      "name": "Empty"
    },
    {
      "x": -9,
      "y": 2,
      "z": 7,
      "name": "Empty"
    },
    {
      "x": -9,
      "y": 3,
      "z": 7,
      "name": "Empty"
    },
    {
      "x": -9,
      "y": 4,
      "z": 7,
      "name": "Empty"
    },
    {
      "x": -9,
      "y": 5,
      "z": 7,
      "name": "Empty"
    },
    {
      "x": -9,
      "y": 6,
      "z": 7,
      "name": "Empty"
    },
    {
      "x": -9,
      "y": 7,
      "z": 7,
      "name": "Empty"
    },
    {
      "x": -9,
      "y": 8,
      "z": 7,
      "name": "Empty"
    },
    {
      "x": -9,
      "y": 9,
      "z": 7,
      "name": "Rock_Shale_Brick"
    },
    {
      "x": -9,
      "y": 0,
      "z": 8,
      "name": "Rock_Shale_Brick"
    },
    {
      "x": -9,
      "y": 1,
      "z": 8,
      "name": "Empty"
    },
    {
      "x": -9,
      "y": 2,
      "z": 8,
      "name": "Empty"
    },
    {
      "x": -9,
      "y": 3,
      "z": 8,
      "name": "Empty"
    },
    {
      "x": -9,
      "y": 4,
      "z": 8,
      "name": "Empty"
    },
    {
      "x": -9,
      "y": 5,
      "z": 8,
      "name": "Empty"
    },
    {
      "x": -9,
      "y": 6,
      "z": 8,
      "name": "Empty"
    },
    {
      "x": -9,
      "y": 7,
      "z": 8,
      "name": "Empty"
    },
    {
      "x": -9,
      "y": 8,
      "z": 8,
      "name": "Empty"
    },
    {
      "x": -9,
      "y": 9,
      "z": 8,
      "name": "Rock_Shale_Cobble"
    },
    {
      "x": -9,
      "y": 0,
      "z": 9,
      "name": "Rock_Shale_Cobble"
    },
    {
      "x": -9,
      "y": 1,
      "z": 9,
      "name": "Empty"
    },
    {
      "x": -9,
      "y": 2,
      "z": 9,
      "name": "Empty"
    },
    {
      "x": -9,
      "y": 3,
      "z": 9,
      "name": "Empty"
    },
    {
      "x": -9,
      "y": 4,
      "z": 9,
      "name": "Empty"
    },
    {
      "x": -9,
      "y": 5,
      "z": 9,
      "name": "Empty"
    },
    {
      "x": -9,
      "y": 6,
      "z": 9,
      "name": "Empty"
    },
    {
      "x": -9,
      "y": 7,
      "z": 9,
      "name": "Empty"
    },
    {
      "x": -9,
      "y": 8,
      "z": 9,
      "name": "Empty"
    },
    {
      "x": -9,
      "y": 9,
      "z": 9,
      "name": "Rock_Shale_Brick"
    },
    {
      "x": -9,
      "y": 0,
      "z": 10,
      "name": "Rock_Shale_Brick"
    },
    {
      "x": -9,
      "y": 1,
      "z": 10,
      "name": "Empty"
    },
    {
      "x": -9,
      "y": 2,
      "z": 10,
      "name": "Empty"
    },
    {
      "x": -9,
      "y": 3,
      "z": 10,
      "name": "Empty"
    },
    {
      "x": -9,
      "y": 4,
      "z": 10,
      "name": "Empty"
    },
    {
      "x": -9,
      "y": 5,
      "z": 10,
      "name": "Empty"
    },
    {
      "x": -9,
      "y": 6,
      "z": 10,
      "name": "Empty"
    },
    {
      "x": -9,
      "y": 7,
      "z": 10,
      "name": "Empty"
    },
    {
      "x": -9,
      "y": 8,
      "z": 10,
      "name": "Empty"
    },
    {
      "x": -9,
      "y": 9,
      "z": 10,
      "name": "Rock_Shale_Brick"
    },
    {
      "x": -9,
      "y": 0,
      "z": 11,
      "name": "Rock_Shale_Brick"
    },
    {
      "x": -9,
      "y": 1,
      "z": 11,
      "name": "Rock_Shale_Brick"
    },
    {
      "x": -9,
      "y": 2,
      "z": 11,
      "name": "Rock_Shale_Brick"
    },
    {
      "x": -9,
      "y": 3,
      "z": 11,
      "name": "Rock_Shale_Brick"
    },
    {
      "x": -9,
      "y": 4,
      "z": 11,
      "name": "Rock_Shale_Cobble"
    },
    {
      "x": -9,
      "y": 5,
      "z": 11,
      "name": "Rock_Shale_Brick"
    },
    {
      "x": -9,
      "y": 6,
      "z": 11,
      "name": "Rock_Shale_Brick"
    },
    {
      "x": -9,
      "y": 7,
      "z": 11,
      "name": "Rock_Shale_Brick"
    },
    {
      "x": -9,
      "y": 8,
      "z": 11,
      "name": "Rock_Shale_Brick"
    },
    {
      "x": -9,
      "y": 9,
      "z": 11,
      "name": "Rock_Shale_Brick"
    },
    {
      "x": -9,
      "y": 0,
      "z": 12,
      "name": "Rock_Shale_Brick"
    },
    {
      "x": -9,
      "y": 1,
      "z": 12,
      "name": "Rock_Shale_Cobble"
    },
    {
      "x": -9,
      "y": 2,
      "z": 12,
      "name": "Rock_Shale_Brick"
    },
    {
      "x": -9,
      "y": 3,
      "z": 12,
      "name": "Rock_Shale_Brick"
    },
    {
      "x": -9,
      "y": 4,
      "z": 12,
      "name": "Rock_Shale_Cobble"
    },
    {
      "x": -9,
      "y": 5,
      "z": 12,
      "name": "Rock_Shale_Brick"
    },
    {
      "x": -9,
      "y": 6,
      "z": 12,
      "name": "Rock_Shale_Brick"
    },
    {
      "x": -9,
      "y": 7,
      "z": 12,
      "name": "Rock_Shale_Cobble"
    },
    {
      "x": -9,
      "y": 8,
      "z": 12,
      "name": "Rock_Shale_Cobble"
    },
    {
      "x": -9,
      "y": 9,
      "z": 12,
      "name": "Rock_Shale_Brick"
    },
    {
      "x": -8,
      "y": 0,
      "z": -12,
      "name": "Rock_Shale_Brick"
    },
    {
      "x": -8,
      "y": 1,
      "z": -12,
      "name": "Rock_Shale_Brick"
    },
    {
      "x": -8,
      "y": 2,
      "z": -12,
      "name": "Rock_Shale_Brick"
    },
    {
      "x": -8,
      "y": 3,
      "z": -12,
      "name": "Rock_Shale_Cobble"
    },
    {
      "x": -8,
      "y": 4,
      "z": -12,
      "name": "Rock_Shale_Brick"
    },
    {
      "x": -8,
      "y": 5,
      "z": -12,
      "name": "Rock_Shale_Cobble"
    },
    {
      "x": -8,
      "y": 6,
      "z": -12,
      "name": "Rock_Shale_Brick"
    },
    {
      "x": -8,
      "y": 7,
      "z": -12,
      "name": "Rock_Shale_Brick"
    },
    {
      "x": -8,
      "y": 8,
      "z": -12,
      "name": "Rock_Shale_Brick"
    },
    {
      "x": -8,
      "y": 9,
      "z": -12,
      "name": "Rock_Shale_Cobble"
    },
    {
      "x": -8,
      "y": 0,
      "z": -11,
      "name": "Rock_Shale_Brick"
    },
    {
      "x": -8,
      "y": 1,
      "z": -11,
      "name": "Rock_Shale_Brick"
    },
    {
      "x": -8,
      "y": 2,
      "z": -11,
      "name": "Rock_Shale_Brick"
    },
    {
      "x": -8,
      "y": 3,
      "z": -11,
      "name": "Rock_Shale_Brick"
    },
    {
      "x": -8,
      "y": 4,
      "z": -11,
      "name": "Rock_Shale_Brick"
    },
    {
      "x": -8,
      "y": 5,
      "z": -11,
      "name": "Rock_Shale_Brick"
    },
    {
      "x": -8,
      "y": 6,
      "z": -11,
      "name": "Rock_Shale_Brick"
    },
    {
      "x": -8,
      "y": 7,
      "z": -11,
      "name": "Rock_Shale_Cobble"
    },
    {
      "x": -8,
      "y": 8,
      "z": -11,
      "name": "Rock_Shale_Brick"
    },
    {
      "x": -8,
      "y": 9,
      "z": -11,
      "name": "Rock_Shale_Brick"
    },
    {
      "x": -8,
      "y": 0,
      "z": -10,
      "name": "Rock_Shale_Brick"
    },
    {
      "x": -8,
      "y": 1,
      "z": -10,
      "name": "Empty"
    },
    {
      "x": -8,
      "y": 2,
      "z": -10,
      "name": "Empty"
    },
    {
      "x": -8,
      "y": 3,
      "z": -10,
      "name": "Empty"
    },
    {
      "x": -8,
      "y": 4,
      "z": -10,
      "name": "Empty"
    },
    {
      "x": -8,
      "y": 5,
      "z": -10,
      "name": "Empty"
    },
    {
      "x": -8,
      "y": 6,
      "z": -10,
      "name": "Empty"
    },
    {
      "x": -8,
      "y": 7,
      "z": -10,
      "name": "Empty"
    },
    {
      "x": -8,
      "y": 8,
      "z": -10,
      "name": "Empty"
    },
    {
      "x": -8,
      "y": 9,
      "z": -10,
      "name": "Rock_Shale_Brick"
    },
    {
      "x": -8,
      "y": 0,
      "z": -9,
      "name": "Rock_Shale_Brick"
    },
    {
      "x": -8,
      "y": 1,
      "z": -9,
      "name": "Empty"
    },
    {
      "x": -8,
      "y": 2,
      "z": -9,
      "name": "Empty"
    },
    {
      "x": -8,
      "y": 3,
      "z": -9,
      "name": "Empty"
    },
    {
      "x": -8,
      "y": 4,
      "z": -9,
      "name": "Empty"
    },
    {
      "x": -8,
      "y": 5,
      "z": -9,
      "name": "Empty"
    },
    {
      "x": -8,
      "y": 6,
      "z": -9,
      "name": "Empty"
    },
    {
      "x": -8,
      "y": 7,
      "z": -9,
      "name": "Empty"
    },
    {
      "x": -8,
      "y": 8,
      "z": -9,
      "name": "Empty"
    },
    {
      "x": -8,
      "y": 9,
      "z": -9,
      "name": "Rock_Shale_Brick"
    },
    {
      "x": -8,
      "y": 0,
      "z": -8,
      "name": "Rock_Shale_Brick"
    },
    {
      "x": -8,
      "y": 1,
      "z": -8,
      "name": "Empty"
    },
    {
      "x": -8,
      "y": 2,
      "z": -8,
      "name": "Empty"
    },
    {
      "x": -8,
      "y": 3,
      "z": -8,
      "name": "Empty"
    },
    {
      "x": -8,
      "y": 4,
      "z": -8,
      "name": "Empty"
    },
    {
      "x": -8,
      "y": 5,
      "z": -8,
      "name": "Empty"
    },
    {
      "x": -8,
      "y": 6,
      "z": -8,
      "name": "Empty"
    },
    {
      "x": -8,
      "y": 7,
      "z": -8,
      "name": "Empty"
    },
    {
      "x": -8,
      "y": 8,
      "z": -8,
      "name": "Empty"
    },
    {
      "x": -8,
      "y": 9,
      "z": -8,
      "name": "Rock_Shale_Cobble"
    },
    {
      "x": -8,
      "y": 0,
      "z": -7,
      "name": "Rock_Shale_Brick"
    },
    {
      "x": -8,
      "y": 1,
      "z": -7,
      "name": "Empty"
    },
    {
      "x": -8,
      "y": 2,
      "z": -7,
      "name": "Empty"
    },
    {
      "x": -8,
      "y": 3,
      "z": -7,
      "name": "Empty"
    },
    {
      "x": -8,
      "y": 4,
      "z": -7,
      "name": "Empty"
    },
    {
      "x": -8,
      "y": 5,
      "z": -7,
      "name": "Empty"
    },
    {
      "x": -8,
      "y": 6,
      "z": -7,
      "name": "Empty"
    },
    {
      "x": -8,
      "y": 7,
      "z": -7,
      "name": "Empty"
    },
    {
      "x": -8,
      "y": 8,
      "z": -7,
      "name": "Empty"
    },
    {
      "x": -8,
      "y": 9,
      "z": -7,
      "name": "Rock_Shale_Cobble"
    },
    {
      "x": -8,
      "y": 0,
      "z": -6,
      "name": "Rock_Shale_Brick"
    },
    {
      "x": -8,
      "y": 1,
      "z": -6,
      "name": "Empty"
    },
    {
      "x": -8,
      "y": 2,
      "z": -6,
      "name": "Empty"
    },
    {
      "x": -8,
      "y": 3,
      "z": -6,
      "name": "Empty"
    },
    {
      "x": -8,
      "y": 4,
      "z": -6,
      "name": "Empty"
    },
    {
      "x": -8,
      "y": 5,
      "z": -6,
      "name": "Empty"
    },
    {
      "x": -8,
      "y": 6,
      "z": -6,
      "name": "Empty"
    },
    {
      "x": -8,
      "y": 7,
      "z": -6,
      "name": "Empty"
    },
    {
      "x": -8,
      "y": 8,
      "z": -6,
      "name": "Empty"
    },
    {
      "x": -8,
      "y": 9,
      "z": -6,
      "name": "Rock_Shale_Brick"
    },
    {
      "x": -8,
      "y": 0,
      "z": -5,
      "name": "Rock_Shale_Cobble"
    },
    {
      "x": -8,
      "y": 1,
      "z": -5,
      "name": "Empty"
    },
    {
      "x": -8,
      "y": 2,
      "z": -5,
      "name": "Empty"
    },
    {
      "x": -8,
      "y": 3,
      "z": -5,
      "name": "Empty"
    },
    {
      "x": -8,
      "y": 4,
      "z": -5,
      "name": "Empty"
    },
    {
      "x": -8,
      "y": 5,
      "z": -5,
      "name": "Empty"
    },
    {
      "x": -8,
      "y": 6,
      "z": -5,
      "name": "Empty"
    },
    {
      "x": -8,
      "y": 7,
      "z": -5,
      "name": "Empty"
    },
    {
      "x": -8,
      "y": 8,
      "z": -5,
      "name": "Empty"
    },
    {
      "x": -8,
      "y": 9,
      "z": -5,
      "name": "Rock_Shale_Brick"
    },
    {
      "x": -8,
      "y": 0,
      "z": -4,
      "name": "Rock_Shale_Brick"
    },
    {
      "x": -8,
      "y": 1,
      "z": -4,
      "name": "Empty"
    },
    {
      "x": -8,
      "y": 2,
      "z": -4,
      "name": "Empty"
    },
    {
      "x": -8,
      "y": 3,
      "z": -4,
      "name": "Empty"
    },
    {
      "x": -8,
      "y": 4,
      "z": -4,
      "name": "Empty"
    },
    {
      "x": -8,
      "y": 5,
      "z": -4,
      "name": "Empty"
    },
    {
      "x": -8,
      "y": 6,
      "z": -4,
      "name": "Empty"
    },
    {
      "x": -8,
      "y": 7,
      "z": -4,
      "name": "Empty"
    },
    {
      "x": -8,
      "y": 8,
      "z": -4,
      "name": "Empty"
    },
    {
      "x": -8,
      "y": 9,
      "z": -4,
      "name": "Rock_Shale_Brick"
    },
    {
      "x": -8,
      "y": 0,
      "z": -3,
      "name": "Rock_Shale_Brick"
    },
    {
      "x": -8,
      "y": 1,
      "z": -3,
      "name": "Empty"
    },
    {
      "x": -8,
      "y": 2,
      "z": -3,
      "name": "Empty"
    },
    {
      "x": -8,
      "y": 3,
      "z": -3,
      "name": "Empty"
    },
    {
      "x": -8,
      "y": 4,
      "z": -3,
      "name": "Empty"
    },
    {
      "x": -8,
      "y": 5,
      "z": -3,
      "name": "Empty"
    },
    {
      "x": -8,
      "y": 6,
      "z": -3,
      "name": "Empty"
    },
    {
      "x": -8,
      "y": 7,
      "z": -3,
      "name": "Empty"
    },
    {
      "x": -8,
      "y": 8,
      "z": -3,
      "name": "Empty"
    },
    {
      "x": -8,
      "y": 9,
      "z": -3,
      "name": "Rock_Shale_Cobble"
    },
    {
      "x": -8,
      "y": 0,
      "z": -2,
      "name": "Rock_Shale_Brick"
    },
    {
      "x": -8,
      "y": 1,
      "z": -2,
      "name": "Empty"
    },
    {
      "x": -8,
      "y": 2,
      "z": -2,
      "name": "Empty"
    },
    {
      "x": -8,
      "y": 3,
      "z": -2,
      "name": "Empty"
    },
    {
      "x": -8,
      "y": 4,
      "z": -2,
      "name": "Empty"
    },
    {
      "x": -8,
      "y": 5,
      "z": -2,
      "name": "Empty"
    },
    {
      "x": -8,
      "y": 6,
      "z": -2,
      "name": "Empty"
    },
    {
      "x": -8,
      "y": 7,
      "z": -2,
      "name": "Empty"
    },
    {
      "x": -8,
      "y": 8,
      "z": -2,
      "name": "Empty"
    },
    {
      "x": -8,
      "y": 9,
      "z": -2,
      "name": "Rock_Shale_Brick"
    },
    {
      "x": -8,
      "y": 0,
      "z": -1,
      "name": "Rock_Shale_Brick"
    },
    {
      "x": -8,
      "y": 1,
      "z": -1,
      "name": "Empty"
    },
    {
      "x": -8,
      "y": 2,
      "z": -1,
      "name": "Empty"
    },
    {
      "x": -8,
      "y": 3,
      "z": -1,
      "name": "Empty"
    },
    {
      "x": -8,
      "y": 4,
      "z": -1,
      "name": "Empty"
    },
    {
      "x": -8,
      "y": 5,
      "z": -1,
      "name": "Empty"
    },
    {
      "x": -8,
      "y": 6,
      "z": -1,
      "name": "Empty"
    },
    {
      "x": -8,
      "y": 7,
      "z": -1,
      "name": "Empty"
    },
    {
      "x": -8,
      "y": 8,
      "z": -1,
      "name": "Empty"
    },
    {
      "x": -8,
      "y": 9,
      "z": -1,
      "name": "Rock_Shale_Cobble"
    },
    {
      "x": -8,
      "y": 0,
      "z": 0,
      "name": "Rock_Shale_Brick"
    },
    {
      "x": -8,
      "y": 1,
      "z": 0,
      "name": "Empty"
    },
    {
      "x": -8,
      "y": 2,
      "z": 0,
      "name": "Empty"
    },
    {
      "x": -8,
      "y": 3,
      "z": 0,
      "name": "Empty"
    },
    {
      "x": -8,
      "y": 4,
      "z": 0,
      "name": "Empty"
    },
    {
      "x": -8,
      "y": 5,
      "z": 0,
      "name": "Empty"
    },
    {
      "x": -8,
      "y": 6,
      "z": 0,
      "name": "Empty"
    },
    {
      "x": -8,
      "y": 7,
      "z": 0,
      "name": "Empty"
    },
    {
      "x": -8,
      "y": 8,
      "z": 0,
      "name": "Empty"
    },
    {
      "x": -8,
      "y": 9,
      "z": 0,
      "name": "Rock_Shale_Brick"
    },
    {
      "x": -8,
      "y": 0,
      "z": 1,
      "name": "Rock_Shale_Cobble"
    },
    {
      "x": -8,
      "y": 1,
      "z": 1,
